Workbook

Sheet CONSOLIDADO DE SESSÕES
F2: GRÁFICO DE REGISTRO DO ACOMPANHANTE TERAPÊUTICO (AT)
C3: NOME DO APRENDIZ
C4: IDADE
C5: PROGRAMA
C6: PROFISSIONAL RESPONSÁVEL
C7: ANO/MÊS EM ANÁLISE
C9: ACERTOS INDEPENDENTES (SEM AJUDA)
C10: VÍNCULO/LINHA DE BASE
B11: HABILIDADES EM TREINAMENTO | C11: DIA 1 | D11: DIA 2 | E11: DIA 3 | F11: INTERVENÇÃO | G11: DIA 4 | H11: DIA 5 | I11: DIA 6 | J11: DIA 7 | K11: DIA 8 | L11: DIA 9 | M11: DIA 10 | N11: DIA 11 | O11: DIA 12 | P11: DIA 13 | Q11: DIA 14 | R11: DIA 15 | S11: DIA 16 | T11: DIA 17 | U11: DIA 18 | V11: DIA 19 | W11: DIA 20 | X11: DIA 21 | Y11: DIA 22 | Z11: DIA 23 | AA11: DIA 24 | AB11: DIA 25 | AC11: DIA 26 | AD11: DIA 27 | AE11: DIA 28 | AF11: DIA 29 | AG11: DIA 30
B12: Seguir as regras do jogo | C12: ='DIA 1'!L7 -> 0 | D12: ='DIA 2'!L7 -> 0 | E12: ='DIA 3'!L7 -> 0 | G12: ='DIA 4'!L7 -> 0 | H12: ='DIA 5'!L7 -> 0 | I12: ='DIA 6'!L7 -> 0 | J12: ='DIA 7'!L7 -> 0 | K12: ='DIA 8'!L7 -> 0 | L12: ='DIA 9'!L7 -> 0 | M12: ='DIA 10'!L7 -> 0 | N12: ='DIA 11'!L7 -> 0 | O12: ='DIA 12'!L7 -> 0 | P12: ='DIA 13'!L7 -> 0 | Q12: ='DIA 14'!L7 -> 0 | R12: ='DIA 15'!L7 -> 0 | S12: ='DIA 16'!L7 -> 0 | T12: ='DIA 17'!L7 -> 0 | U12: ='DIA 18'!L7 -> 0 | V12: ='DIA 19'!L7 -> 0 | W12: ='DIA 20'!L7 -> 0 | X12: ='DIA 21'!L7 -> 0 | Y12: ='DIA 22'!L7 -> 0 | Z12: ='DIA 23'!L7 -> 0 | AA12: ='DIA 24'!L7 -> 0 | AB12: ='DIA 25'!L7 -> 0 | AC12: ='DIA 26'!L7 -> 0 | AD12: ='DIA 27'!L7 -> 0 | AE12: ='DIA 28'!L7 -> 0 | AF12: ='DIA 29'!L7 -> 0 | AG12: ='DIA 30'!L7 -> 0
B13: Esperar a sua vez | C13: ='DIA 1'!L12 -> 0 | D13: ='DIA 2'!L12 -> 0 | E13: ='DIA 3'!L12 -> 0 | G13: ='DIA 4'!L12 -> 0 | H13: ='DIA 5'!L12 -> 0 | I13: ='DIA 6'!L12 -> 0 | J13: ='DIA 7'!L12 -> 0 | K13: ='DIA 8'!L12 -> 0 | L13: ='DIA 9'!L12 -> 0 | M13: ='DIA 10'!L12 -> 0 | N13: ='DIA 11'!L12 -> 0 | O13: ='DIA 12'!L12 -> 0 | P13: ='DIA 13'!L12 -> 0 | Q13: ='DIA 14'!L12 -> 0 | R13: ='DIA 15'!L12 -> 0 | S13: ='DIA 16'!L12 -> 0 | T13: ='DIA 17'!L12 -> 0 | U13: ='DIA 18'!L12 -> 0 | V13: ='DIA 19'!L12 -> 0 | W13: ='DIA 20'!L12 -> 0 | X13: ='DIA 21'!L12 -> 0 | Y13: ='DIA 22'!L12 -> 0 | Z13: ='DIA 23'!L12 -> 0 | AA13: ='DIA 24'!L12 -> 0 | AB13: ='DIA 25'!L12 -> 0 | AC13: ='DIA 26'!L12 -> 0 | AD13: ='DIA 27'!L12 -> 0 | AE13: ='DIA 28'!L12 -> 0 | AF13: ='DIA 29'!L12 -> 0 | AG13: ='DIA 30'!L12 -> 0
B14: Lidar com frustração de perder | C14: ='DIA 1'!L17 -> 0 | D14: ='DIA 2'!L17 -> 0 | E14: ='DIA 3'!L17 -> 0 | G14: ='DIA 4'!L17 -> 0 | H14: ='DIA 5'!L17 -> 0 | I14: ='DIA 6'!L17 -> 0 | J14: ='DIA 7'!L17 -> 0 | K14: ='DIA 8'!L17 -> 0 | L14: ='DIA 9'!L17 -> 0 | M14: ='DIA 10'!L17 -> 0 | N14: ='DIA 11'!L17 -> 0 | O14: ='DIA 12'!L17 -> 0 | P14: ='DIA 13'!L17 -> 0 | Q14: ='DIA 14'!L17 -> 0 | R14: ='DIA 15'!L17 -> 0 | S14: ='DIA 16'!L17 -> 0 | T14: ='DIA 17'!L17 -> 0 | U14: ='DIA 18'!L17 -> 0 | V14: ='DIA 19'!L17 -> 0 | W14: ='DIA 20'!L17 -> 0 | X14: ='DIA 21'!L17 -> 0 | Y14: ='DIA 22'!L17 -> 0 | Z14: ='DIA 23'!L17 -> 0 | AA14: ='DIA 24'!L17 -> 0 | AB14: ='DIA 25'!L17 -> 0 | AC14: ='DIA 26'!L17 -> 0 | AD14: ='DIA 27'!L17 -> 0 | AE14: ='DIA 28'!L17 -> 0 | AF14: ='DIA 29'!L17 -> 0 | AG14: ='DIA 30'!L17 -> 0
B15: Permanecer no jogo até o final | C15: ='DIA 1'!L22 -> 0 | D15: ='DIA 2'!L22 -> 0 | E15: ='DIA 3'!L22 -> 0 | G15: ='DIA 4'!L22 -> 0 | H15: ='DIA 5'!L22 -> 0 | I15: ='DIA 6'!L22 -> 0 | J15: ='DIA 7'!L22 -> 0 | K15: ='DIA 8'!L22 -> 0 | L15: ='DIA 9'!L22 -> 0 | M15: ='DIA 10'!L22 -> 0 | N15: ='DIA 11'!L22 -> 0 | O15: ='DIA 12'!L22 -> 0 | P15: ='DIA 13'!L22 -> 0 | Q15: ='DIA 14'!L22 -> 0 | R15: ='DIA 15'!L22 -> 0 | S15: ='DIA 16'!L22 -> 0 | T15: ='DIA 17'!L22 -> 0 | U15: ='DIA 18'!L22 -> 0 | V15: ='DIA 19'!L22 -> 0 | W15: ='DIA 20'!L22 -> 0 | X15: ='DIA 21'!L22 -> 0 | Y15: ='DIA 22'!L22 -> 0 | Z15: ='DIA 23'!L22 -> 0 | AA15: ='DIA 24'!L22 -> 0 | AB15: ='DIA 25'!L22 -> 0 | AC15: ='DIA 26'!L22 -> 0 | AD15: ='DIA 27'!L22 -> 0 | AE15: ='DIA 28'!L22 -> 0 | AF15: ='DIA 29'!L22 -> 0 | AG15: ='DIA 30'!L22 -> 0
B16: Aceitar o fim da brincadeira sem chorar | C16: ='DIA 1'!L27 -> 0 | D16: ='DIA 2'!L27 -> 0 | E16: ='DIA 3'!L27 -> 0 | G16: ='DIA 4'!L27 -> 0 | H16: ='DIA 5'!L27 -> 0 | I16: ='DIA 6'!L27 -> 0 | J16: ='DIA 7'!L27 -> 0 | K16: ='DIA 8'!L27 -> 0 | L16: ='DIA 9'!L27 -> 0 | M16: ='DIA 10'!L27 -> 0 | N16: ='DIA 11'!L27 -> 0 | O16: ='DIA 12'!L27 -> 0 | P16: ='DIA 13'!L27 -> 0 | Q16: ='DIA 14'!L27 -> 0 | R16: ='DIA 15'!L27 -> 0 | S16: ='DIA 16'!L27 -> 0 | T16: ='DIA 17'!L27 -> 0 | U16: ='DIA 18'!L27 -> 0 | V16: ='DIA 19'!L27 -> 0 | W16: ='DIA 20'!L27 -> 0 | X16: ='DIA 21'!L27 -> 0 | Y16: ='DIA 22'!L27 -> 0 | Z16: ='DIA 23'!L27 -> 0 | AA16: ='DIA 24'!L27 -> 0 | AB16: ='DIA 25'!L27 -> 0 | AC16: ='DIA 26'!L27 -> 0 | AD16: ='DIA 27'!L27 -> 0 | AE16: ='DIA 28'!L27 -> 0 | AF16: ='DIA 29'!L27 -> 0 | AG16: ='DIA 30'!L27 -> 0
B18: HABILIDADES EM MANUTENÇÃO

Sheet DIA 1
C2: PROTOCOLO DE APLICAÇÃO E REGISTRO | D2: TREINO
E3: DATA
D4: LEGENDA | F4: I = Resposta sem ajuda (independente) P = Resposta com ajuda parcial T = Resposta com ajuda total
B6: HABILIDADE EM TREINAMENTO | C6: REFORÇADOR | D6: TENTATIVAS | E6: 1 | F6: 2 | G6: 3 | H6: 4 | I6: 5 | J6: 6 | K6: TOTAL | L6: % | M6: OBSERVAÇÕES
B7: Seguir as regras do jogo | D7: I | K7: =SUM(E7:J7) -> 0 | L7: =K7/6 -> 0
D8: P | K8: =SUM(E8:J8) -> 0 | L8: =K8/6 -> 0
D9: T | K9: =SUM(E9:J9) -> 0 | L9: =K9/6 -> 0
B11: HABILIDADE EM TREINAMENTO | C11: REFORÇADOR | D11: TENTATIVAS | E11: 1 | F11: 2 | G11: 3 | H11: 4 | I11: 5 | J11: 6 | K11: TOTAL | L11: % | M11: OBSERVAÇÕES
B12: Esperar a sua vez | D12: I | K12: =SUM(E12:J12) -> 0 | L12: =K12/6 -> 0
D13: P | K13: =SUM(E13:J13) -> 0 | L13: =K13/6 -> 0
D14: T | K14: =SUM(E14:J14) -> 0 | L14: =K14/6 -> 0
B16: HABILIDADE EM TREINAMENTO | C16: REFORÇADOR | D16: TENTATIVAS | E16: 1 | F16: 2 | G16: 3 | H16: 4 | I16: 5 | J16: 6 | K16: TOTAL | L16: % | M16: OBSERVAÇÕES
B17: Lidar com frustração de perder | D17: I | K17: =SUM(E17:J17) -> 0 | L17: =K17/6 -> 0
D18: P | K18: =SUM(E18:J18) -> 0 | L18: =K18/6 -> 0
D19: T | K19: =SUM(E19:J19) -> 0 | L19: =K19/6 -> 0
B21: HABILIDADE EM TREINAMENTO | C21: REFORÇADOR | D21: TENTATIVAS | E21: 1 | F21: 2 | G21: 3 | H21: 4 | I21: 5 | J21: 6 | K21: TOTAL | L21: % | M21: OBSERVAÇÕES
B22: Permanecer no jogo até o final | D22: I | K22: =SUM(E22:J22) -> 0 | L22: =K22/6 -> 0
D23: P | K23: =SUM(E23:J23) -> 0 | L23: =K23/6 -> 0
D24: T | K24: =SUM(E24:J24) -> 0 | L24: =K24/6 -> 0
B26: HABILIDADE EM TREINAMENTO | C26: REFORÇADOR | D26: TENTATIVAS | E26: 1 | F26: 2 | G26: 3 | H26: 4 | I26: 5 | J26: 6 | K26: TOTAL | L26: % | M26: OBSERVAÇÕES
B27: Aceitar o fim da brincadeira sem chorar | D27: I | K27: =SUM(E27:J27) -> 0 | L27: =K27/6 -> 0
D28: P | K28: =SUM(E28:J28) -> 0 | L28: =K28/6 -> 0
D29: T | K29: =SUM(E29:J29) -> 0 | L29: =K29/6 -> 0

Sheet DIA 2
C2: PROTOCOLO DE APLICAÇÃO E REGISTRO | D2: TREINO
E3: DATA
D4: LEGENDA | F4: I = Resposta sem ajuda (independente) P = Resposta com ajuda parcial T = Resposta com ajuda total
B6: HABILIDADE EM TREINAMENTO | C6: REFORÇADOR | D6: TENTATIVAS | E6: 1 | F6: 2 | G6: 3 | H6: 4 | I6: 5 | J6: 6 | K6: TOTAL | L6: % | M6: OBSERVAÇÕES
B7: Seguir as regras do jogo | D7: I | K7: =SUM(E7:J7) -> 0 | L7: =K7/6 -> 0
D8: P | K8: =SUM(E8:J8) -> 0 | L8: =K8/6 -> 0
D9: T | K9: =SUM(E9:J9) -> 0 | L9: =K9/6 -> 0
B11: HABILIDADE EM TREINAMENTO | C11: REFORÇADOR | D11: TENTATIVAS | E11: 1 | F11: 2 | G11: 3 | H11: 4 | I11: 5 | J11: 6 | K11: TOTAL | L11: % | M11: OBSERVAÇÕES
B12: Esperar a sua vez | D12: I | K12: =SUM(E12:J12) -> 0 | L12: =K12/6 -> 0
D13: P | K13: =SUM(E13:J13) -> 0 | L13: =K13/6 -> 0
D14: T | K14: =SUM(E14:J14) -> 0 | L14: =K14/6 -> 0
B16: HABILIDADE EM TREINAMENTO | C16: REFORÇADOR | D16: TENTATIVAS | E16: 1 | F16: 2 | G16: 3 | H16: 4 | I16: 5 | J16: 6 | K16: TOTAL | L16: % | M16: OBSERVAÇÕES
B17: Lidar com frustração de perder | D17: I | K17: =SUM(E17:J17) -> 0 | L17: =K17/6 -> 0
D18: P | K18: =SUM(E18:J18) -> 0 | L18: =K18/6 -> 0
D19: T | K19: =SUM(E19:J19) -> 0 | L19: =K19/6 -> 0
B21: HABILIDADE EM TREINAMENTO | C21: REFORÇADOR | D21: TENTATIVAS | E21: 1 | F21: 2 | G21: 3 | H21: 4 | I21: 5 | J21: 6 | K21: TOTAL | L21: % | M21: OBSERVAÇÕES
B22: Permanecer no jogo até o final | D22: I | K22: =SUM(E22:J22) -> 0 | L22: =K22/6 -> 0
D23: P | K23: =SUM(E23:J23) -> 0 | L23: =K23/6 -> 0
D24: T | K24: =SUM(E24:J24) -> 0 | L24: =K24/6 -> 0
B26: HABILIDADE EM TREINAMENTO | C26: REFORÇADOR | D26: TENTATIVAS | E26: 1 | F26: 2 | G26: 3 | H26: 4 | I26: 5 | J26: 6 | K26: TOTAL | L26: % | M26: OBSERVAÇÕES
B27: Aceitar o fim da brincadeira sem chorar | D27: I | K27: =SUM(E27:J27) -> 0 | L27: =K27/6 -> 0
D28: P | K28: =SUM(E28:J28) -> 0 | L28: =K28/6 -> 0
D29: T | K29: =SUM(E29:J29) -> 0 | L29: =K29/6 -> 0

Sheet DIA 3
C2: PROTOCOLO DE APLICAÇÃO E REGISTRO | D2: TREINO
E3: DATA
D4: LEGENDA | F4: I = Resposta sem ajuda (independente) P = Resposta com ajuda parcial T = Resposta com ajuda total
B6: HABILIDADE EM TREINAMENTO | C6: REFORÇADOR | D6: TENTATIVAS | E6: 1 | F6: 2 | G6: 3 | H6: 4 | I6: 5 | J6: 6 | K6: TOTAL | L6: % | M6: OBSERVAÇÕES
B7: Seguir as regras do jogo | D7: I | K7: =SUM(E7:J7) -> 0 | L7: =K7/6 -> 0
D8: P | K8: =SUM(E8:J8) -> 0 | L8: =K8/6 -> 0
D9: T | K9: =SUM(E9:J9) -> 0 | L9: =K9/6 -> 0
B11: HABILIDADE EM TREINAMENTO | C11: REFORÇADOR | D11: TENTATIVAS | E11: 1 | F11: 2 | G11: 3 | H11: 4 | I11: 5 | J11: 6 | K11: TOTAL | L11: % | M11: OBSERVAÇÕES
B12: Esperar a sua vez | D12: I | K12: =SUM(E12:J12) -> 0 | L12: =K12/6 -> 0
D13: P | K13: =SUM(E13:J13) -> 0 | L13: =K13/6 -> 0
D14: T | K14: =SUM(E14:J14) -> 0 | L14: =K14/6 -> 0
B16: HABILIDADE EM TREINAMENTO | C16: REFORÇADOR | D16: TENTATIVAS | E16: 1 | F16: 2 | G16: 3 | H16: 4 | I16: 5 | J16: 6 | K16: TOTAL | L16: % | M16: OBSERVAÇÕES
B17: Lidar com frustração de perder | D17: I | K17: =SUM(E17:J17) -> 0 | L17: =K17/6 -> 0
D18: P | K18: =SUM(E18:J18) -> 0 | L18: =K18/6 -> 0
D19: T | K19: =SUM(E19:J19) -> 0 | L19: =K19/6 -> 0
B21: HABILIDADE EM TREINAMENTO | C21: REFORÇADOR | D21: TENTATIVAS | E21: 1 | F21: 2 | G21: 3 | H21: 4 | I21: 5 | J21: 6 | K21: TOTAL | L21: % | M21: OBSERVAÇÕES
B22: Permanecer no jogo até o final | D22: I | K22: =SUM(E22:J22) -> 0 | L22: =K22/6 -> 0
D23: P | K23: =SUM(E23:J23) -> 0 | L23: =K23/6 -> 0
D24: T | K24: =SUM(E24:J24) -> 0 | L24: =K24/6 -> 0
B26: HABILIDADE EM TREINAMENTO | C26: REFORÇADOR | D26: TENTATIVAS | E26: 1 | F26: 2 | G26: 3 | H26: 4 | I26: 5 | J26: 6 | K26: TOTAL | L26: % | M26: OBSERVAÇÕES
B27: Aceitar o fim da brincadeira sem chorar | D27: I | K27: =SUM(E27:J27) -> 0 | L27: =K27/6 -> 0
D28: P | K28: =SUM(E28:J28) -> 0 | L28: =K28/6 -> 0
D29: T | K29: =SUM(E29:J29) -> 0 | L29: =K29/6 -> 0

Sheet DIA 4
C2: PROTOCOLO DE APLICAÇÃO E REGISTRO | D2: TREINO
E3: DATA
D4: LEGENDA | F4: I = Resposta sem ajuda (independente) P = Resposta com ajuda parcial T = Resposta com ajuda total
B6: HABILIDADE EM TREINAMENTO | C6: REFORÇADOR | D6: TENTATIVAS | E6: 1 | F6: 2 | G6: 3 | H6: 4 | I6: 5 | J6: 6 | K6: TOTAL | L6: % | M6: OBSERVAÇÕES
B7: Seguir as regras do jogo | D7: I | K7: =SUM(E7:J7) -> 0 | L7: =K7/6 -> 0
D8: P | K8: =SUM(E8:J8) -> 0 | L8: =K8/6 -> 0
D9: T | K9: =SUM(E9:J9) -> 0 | L9: =K9/6 -> 0
B11: HABILIDADE EM TREINAMENTO | C11: REFORÇADOR | D11: TENTATIVAS | E11: 1 | F11: 2 | G11: 3 | H11: 4 | I11: 5 | J11: 6 | K11: TOTAL | L11: % | M11: OBSERVAÇÕES
B12: Esperar a sua vez | D12: I | K12: =SUM(E12:J12) -> 0 | L12: =K12/6 -> 0
D13: P | K13: =SUM(E13:J13) -> 0 | L13: =K13/6 -> 0
D14: T | K14: =SUM(E14:J14) -> 0 | L14: =K14/6 -> 0
B16: HABILIDADE EM TREINAMENTO | C16: REFORÇADOR | D16: TENTATIVAS | E16: 1 | F16: 2 | G16: 3 | H16: 4 | I16: 5 | J16: 6 | K16: TOTAL | L16: % | M16: OBSERVAÇÕES
B17: Lidar com frustração de perder | D17: I | K17: =SUM(E17:J17) -> 0 | L17: =K17/6 -> 0
D18: P | K18: =SUM(E18:J18) -> 0 | L18: =K18/6 -> 0
D19: T | K19: =SUM(E19:J19) -> 0 | L19: =K19/6 -> 0
B21: HABILIDADE EM TREINAMENTO | C21: REFORÇADOR | D21: TENTATIVAS | E21: 1 | F21: 2 | G21: 3 | H21: 4 | I21: 5 | J21: 6 | K21: TOTAL | L21: % | M21: OBSERVAÇÕES
B22: Permanecer no jogo até o final | D22: I | K22: =SUM(E22:J22) -> 0 | L22: =K22/6 -> 0
D23: P | K23: =SUM(E23:J23) -> 0 | L23: =K23/6 -> 0
D24: T | K24: =SUM(E24:J24) -> 0 | L24: =K24/6 -> 0
B26: HABILIDADE EM TREINAMENTO | C26: REFORÇADOR | D26: TENTATIVAS | E26: 1 | F26: 2 | G26: 3 | H26: 4 | I26: 5 | J26: 6 | K26: TOTAL | L26: % | M26: OBSERVAÇÕES
B27: Aceitar o fim da brincadeira sem chorar | D27: I | K27: =SUM(E27:J27) -> 0 | L27: =K27/6 -> 0
D28: P | K28: =SUM(E28:J28) -> 0 | L28: =K28/6 -> 0
D29: T | K29: =SUM(E29:J29) -> 0 | L29: =K29/6 -> 0

Sheet DIA 5
C2: PROTOCOLO DE APLICAÇÃO E REGISTRO | D2: TREINO
E3: DATA
D4: LEGENDA | F4: I = Resposta sem ajuda (independente) P = Resposta com ajuda parcial T = Resposta com ajuda total
B6: HABILIDADE EM TREINAMENTO | C6: REFORÇADOR | D6: TENTATIVAS | E6: 1 | F6: 2 | G6: 3 | H6: 4 | I6: 5 | J6: 6 | K6: TOTAL | L6: % | M6: OBSERVAÇÕES
B7: Seguir as regras do jogo | D7: I | K7: =SUM(E7:J7) -> 0 | L7: =K7/6 -> 0
D8: P | K8: =SUM(E8:J8) -> 0 | L8: =K8/6 -> 0
D9: T | K9: =SUM(E9:J9) -> 0 | L9: =K9/6 -> 0
B11: HABILIDADE EM TREINAMENTO | C11: REFORÇADOR | D11: TENTATIVAS | E11: 1 | F11: 2 | G11: 3 | H11: 4 | I11: 5 | J11: 6 | K11: TOTAL | L11: % | M11: OBSERVAÇÕES
B12: Esperar a sua vez | D12: I | K12: =SUM(E12:J12) -> 0 | L12: =K12/6 -> 0
D13: P | K13: =SUM(E13:J13) -> 0 | L13: =K13/6 -> 0
D14: T | K14: =SUM(E14:J14) -> 0 | L14: =K14/6 -> 0
B16: HABILIDADE EM TREINAMENTO | C16: REFORÇADOR | D16: TENTATIVAS | E16: 1 | F16: 2 | G16: 3 | H16: 4 | I16: 5 | J16: 6 | K16: TOTAL | L16: % | M16: OBSERVAÇÕES
B17: Lidar com frustração de perder | D17: I | K17: =SUM(E17:J17) -> 0 | L17: =K17/6 -> 0
D18: P | K18: =SUM(E18:J18) -> 0 | L18: =K18/6 -> 0
D19: T | K19: =SUM(E19:J19) -> 0 | L19: =K19/6 -> 0
B21: HABILIDADE EM TREINAMENTO | C21: REFORÇADOR | D21: TENTATIVAS | E21: 1 | F21: 2 | G21: 3 | H21: 4 | I21: 5 | J21: 6 | K21: TOTAL | L21: % | M21: OBSERVAÇÕES
B22: Permanecer no jogo até o final | D22: I | K22: =SUM(E22:J22) -> 0 | L22: =K22/6 -> 0
D23: P | K23: =SUM(E23:J23) -> 0 | L23: =K23/6 -> 0
D24: T | K24: =SUM(E24:J24) -> 0 | L24: =K24/6 -> 0
B26: HABILIDADE EM TREINAMENTO | C26: REFORÇADOR | D26: TENTATIVAS | E26: 1 | F26: 2 | G26: 3 | H26: 4 | I26: 5 | J26: 6 | K26: TOTAL | L26: % | M26: OBSERVAÇÕES
B27: Aceitar o fim da brincadeira sem chorar | D27: I | K27: =SUM(E27:J27) -> 0 | L27: =K27/6 -> 0
D28: P | K28: =SUM(E28:J28) -> 0 | L28: =K28/6 -> 0
D29: T | K29: =SUM(E29:J29) -> 0 | L29: =K29/6 -> 0

Sheet DIA 6
C2: PROTOCOLO DE APLICAÇÃO E REGISTRO | D2: TREINO
E3: DATA
D4: LEGENDA | F4: I = Resposta sem ajuda (independente) P = Resposta com ajuda parcial T = Resposta com ajuda total
B6: HABILIDADE EM TREINAMENTO | C6: REFORÇADOR | D6: TENTATIVAS | E6: 1 | F6: 2 | G6: 3 | H6: 4 | I6: 5 | J6: 6 | K6: TOTAL | L6: % | M6: OBSERVAÇÕES
B7: Seguir as regras do jogo | D7: I | K7: =SUM(E7:J7) -> 0 | L7: =K7/6 -> 0
D8: P | K8: =SUM(E8:J8) -> 0 | L8: =K8/6 -> 0
D9: T | K9: =SUM(E9:J9) -> 0 | L9: =K9/6 -> 0
B11: HABILIDADE EM TREINAMENTO | C11: REFORÇADOR | D11: TENTATIVAS | E11: 1 | F11: 2 | G11: 3 | H11: 4 | I11: 5 | J11: 6 | K11: TOTAL | L11: % | M11: OBSERVAÇÕES
B12: Esperar a sua vez | D12: I | K12: =SUM(E12:J12) -> 0 | L12: =K12/6 -> 0
D13: P | K13: =SUM(E13:J13) -> 0 | L13: =K13/6 -> 0
D14: T | K14: =SUM(E14:J14) -> 0 | L14: =K14/6 -> 0
B16: HABILIDADE EM TREINAMENTO | C16: REFORÇADOR | D16: TENTATIVAS | E16: 1 | F16: 2 | G16: 3 | H16: 4 | I16: 5 | J16: 6 | K16: TOTAL | L16: % | M16: OBSERVAÇÕES
B17: Lidar com frustração de perder | D17: I | K17: =SUM(E17:J17) -> 0 | L17: =K17/6 -> 0
D18: P | K18: =SUM(E18:J18) -> 0 | L18: =K18/6 -> 0
D19: T | K19: =SUM(E19:J19) -> 0 | L19: =K19/6 -> 0
B21: HABILIDADE EM TREINAMENTO | C21: REFORÇADOR | D21: TENTATIVAS | E21: 1 | F21: 2 | G21: 3 | H21: 4 | I21: 5 | J21: 6 | K21: TOTAL | L21: % | M21: OBSERVAÇÕES
B22: Permanecer no jogo até o final | D22: I | K22: =SUM(E22:J22) -> 0 | L22: =K22/6 -> 0
D23: P | K23: =SUM(E23:J23) -> 0 | L23: =K23/6 -> 0
D24: T | K24: =SUM(E24:J24) -> 0 | L24: =K24/6 -> 0
B26: HABILIDADE EM TREINAMENTO | C26: REFORÇADOR | D26: TENTATIVAS | E26: 1 | F26: 2 | G26: 3 | H26: 4 | I26: 5 | J26: 6 | K26: TOTAL | L26: % | M26: OBSERVAÇÕES
B27: Aceitar o fim da brincadeira sem chorar | D27: I | K27: =SUM(E27:J27) -> 0 | L27: =K27/6 -> 0
D28: P | K28: =SUM(E28:J28) -> 0 | L28: =K28/6 -> 0
D29: T | K29: =SUM(E29:J29) -> 0 | L29: =K29/6 -> 0

Sheet DIA 7
C2: PROTOCOLO DE APLICAÇÃO E REGISTRO | D2: TREINO
E3: DATA
D4: LEGENDA | F4: I = Resposta sem ajuda (independente) P = Resposta com ajuda parcial T = Resposta com ajuda total
B6: HABILIDADE EM TREINAMENTO | C6: REFORÇADOR | D6: TENTATIVAS | E6: 1 | F6: 2 | G6: 3 | H6: 4 | I6: 5 | J6: 6 | K6: TOTAL | L6: % | M6: OBSERVAÇÕES
B7: Seguir as regras do jogo | D7: I | K7: =SUM(E7:J7) -> 0 | L7: =K7/6 -> 0
D8: P | K8: =SUM(E8:J8) -> 0 | L8: =K8/6 -> 0
D9: T | K9: =SUM(E9:J9) -> 0 | L9: =K9/6 -> 0
B11: HABILIDADE EM TREINAMENTO | C11: REFORÇADOR | D11: TENTATIVAS | E11: 1 | F11: 2 | G11: 3 | H11: 4 | I11: 5 | J11: 6 | K11: TOTAL | L11: % | M11: OBSERVAÇÕES
B12: Esperar a sua vez | D12: I | K12: =SUM(E12:J12) -> 0 | L12: =K12/6 -> 0
D13: P | K13: =SUM(E13:J13) -> 0 | L13: =K13/6 -> 0
D14: T | K14: =SUM(E14:J14) -> 0 | L14: =K14/6 -> 0
B16: HABILIDADE EM TREINAMENTO | C16: REFORÇADOR | D16: TENTATIVAS | E16: 1 | F16: 2 | G16: 3 | H16: 4 | I16: 5 | J16: 6 | K16: TOTAL | L16: % | M16: OBSERVAÇÕES
B17: Lidar com frustração de perder | D17: I | K17: =SUM(E17:J17) -> 0 | L17: =K17/6 -> 0
D18: P | K18: =SUM(E18:J18) -> 0 | L18: =K18/6 -> 0
D19: T | K19: =SUM(E19:J19) -> 0 | L19: =K19/6 -> 0
B21: HABILIDADE EM TREINAMENTO | C21: REFORÇADOR | D21: TENTATIVAS | E21: 1 | F21: 2 | G21: 3 | H21: 4 | I21: 5 | J21: 6 | K21: TOTAL | L21: % | M21: OBSERVAÇÕES
B22: Permanecer no jogo até o final | D22: I | K22: =SUM(E22:J22) -> 0 | L22: =K22/6 -> 0
D23: P | K23: =SUM(E23:J23) -> 0 | L23: =K23/6 -> 0
D24: T | K24: =SUM(E24:J24) -> 0 | L24: =K24/6 -> 0
B26: HABILIDADE EM TREINAMENTO | C26: REFORÇADOR | D26: TENTATIVAS | E26: 1 | F26: 2 | G26: 3 | H26: 4 | I26: 5 | J26: 6 | K26: TOTAL | L26: % | M26: OBSERVAÇÕES
B27: Aceitar o fim da brincadeira sem chorar | D27: I | K27: =SUM(E27:J27) -> 0 | L27: =K27/6 -> 0
D28: P | K28: =SUM(E28:J28) -> 0 | L28: =K28/6 -> 0
D29: T | K29: =SUM(E29:J29) -> 0 | L29: =K29/6 -> 0

Sheet DIA 8
C2: PROTOCOLO DE APLICAÇÃO E REGISTRO | D2: TREINO
E3: DATA
D4: LEGENDA | F4: I = Resposta sem ajuda (independente) P = Resposta com ajuda parcial T = Resposta com ajuda total
B6: HABILIDADE EM TREINAMENTO | C6: REFORÇADOR | D6: TENTATIVAS | E6: 1 | F6: 2 | G6: 3 | H6: 4 | I6: 5 | J6: 6 | K6: TOTAL | L6: % | M6: OBSERVAÇÕES
B7: Seguir as regras do jogo | D7: I | K7: =SUM(E7:J7) -> 0 | L7: =K7/6 -> 0
D8: P | K8: =SUM(E8:J8) -> 0 | L8: =K8/6 -> 0
D9: T | K9: =SUM(E9:J9) -> 0 | L9: =K9/6 -> 0
B11: HABILIDADE EM TREINAMENTO | C11: REFORÇADOR | D11: TENTATIVAS | E11: 1 | F11: 2 | G11: 3 | H11: 4 | I11: 5 | J11: 6 | K11: TOTAL | L11: % | M11: OBSERVAÇÕES
B12: Esperar a sua vez | D12: I | K12: =SUM(E12:J12) -> 0 | L12: =K12/6 -> 0
D13: P | K13: =SUM(E13:J13) -> 0 | L13: =K13/6 -> 0
D14: T | K14: =SUM(E14:J14) -> 0 | L14: =K14/6 -> 0
B16: HABILIDADE EM TREINAMENTO | C16: REFORÇADOR | D16: TENTATIVAS | E16: 1 | F16: 2 | G16: 3 | H16: 4 | I16: 5 | J16: 6 | K16: TOTAL | L16: % | M16: OBSERVAÇÕES
B17: Lidar com frustração de perder | D17: I | K17: =SUM(E17:J17) -> 0 | L17: =K17/6 -> 0
D18: P | K18: =SUM(E18:J18) -> 0 | L18: =K18/6 -> 0
D19: T | K19: =SUM(E19:J19) -> 0 | L19: =K19/6 -> 0
B21: HABILIDADE EM TREINAMENTO | C21: REFORÇADOR | D21: TENTATIVAS | E21: 1 | F21: 2 | G21: 3 | H21: 4 | I21: 5 | J21: 6 | K21: TOTAL | L21: % | M21: OBSERVAÇÕES
B22: Permanecer no jogo até o final | D22: I | K22: =SUM(E22:J22) -> 0 | L22: =K22/6 -> 0
D23: P | K23: =SUM(E23:J23) -> 0 | L23: =K23/6 -> 0
D24: T | K24: =SUM(E24:J24) -> 0 | L24: =K24/6 -> 0
B26: HABILIDADE EM TREINAMENTO | C26: REFORÇADOR | D26: TENTATIVAS | E26: 1 | F26: 2 | G26: 3 | H26: 4 | I26: 5 | J26: 6 | K26: TOTAL | L26: % | M26: OBSERVAÇÕES
B27: Aceitar o fim da brincadeira sem chorar | D27: I | K27: =SUM(E27:J27) -> 0 | L27: =K27/6 -> 0
D28: P | K28: =SUM(E28:J28) -> 0 | L28: =K28/6 -> 0
D29: T | K29: =SUM(E29:J29) -> 0 | L29: =K29/6 -> 0

Sheet DIA 9
C2: PROTOCOLO DE APLICAÇÃO E REGISTRO | D2: TREINO
E3: DATA
D4: LEGENDA | F4: I = Resposta sem ajuda (independente) P = Resposta com ajuda parcial T = Resposta com ajuda total
B6: HABILIDADE EM TREINAMENTO | C6: REFORÇADOR | D6: TENTATIVAS | E6: 1 | F6: 2 | G6: 3 | H6: 4 | I6: 5 | J6: 6 | K6: TOTAL | L6: % | M6: OBSERVAÇÕES
B7: Seguir as regras do jogo | D7: I | K7: =SUM(E7:J7) -> 0 | L7: =K7/6 -> 0
D8: P | K8: =SUM(E8:J8) -> 0 | L8: =K8/6 -> 0
D9: T | K9: =SUM(E9:J9) -> 0 | L9: =K9/6 -> 0
B11: HABILIDADE EM TREINAMENTO | C11: REFORÇADOR | D11: TENTATIVAS | E11: 1 | F11: 2 | G11: 3 | H11: 4 | I11: 5 | J11: 6 | K11: TOTAL | L11: % | M11: OBSERVAÇÕES
B12: Esperar a sua vez | D12: I | K12: =SUM(E12:J12) -> 0 | L12: =K12/6 -> 0
D13: P | K13: =SUM(E13:J13) -> 0 | L13: =K13/6 -> 0
D14: T | K14: =SUM(E14:J14) -> 0 | L14: =K14/6 -> 0
B16: HABILIDADE EM TREINAMENTO | C16: REFORÇADOR | D16: TENTATIVAS | E16: 1 | F16: 2 | G16: 3 | H16: 4 | I16: 5 | J16: 6 | K16: TOTAL | L16: % | M16: OBSERVAÇÕES
B17: Lidar com frustração de perder | D17: I | K17: =SUM(E17:J17) -> 0 | L17: =K17/6 -> 0
D18: P | K18: =SUM(E18:J18) -> 0 | L18: =K18/6 -> 0
D19: T | K19: =SUM(E19:J19) -> 0 | L19: =K19/6 -> 0
B21: HABILIDADE EM TREINAMENTO | C21: REFORÇADOR | D21: TENTATIVAS | E21: 1 | F21: 2 | G21: 3 | H21: 4 | I21: 5 | J21: 6 | K21: TOTAL | L21: % | M21: OBSERVAÇÕES
B22: Permanecer no jogo até o final | D22: I | K22: =SUM(E22:J22) -> 0 | L22: =K22/6 -> 0
D23: P | K23: =SUM(E23:J23) -> 0 | L23: =K23/6 -> 0
D24: T | K24: =SUM(E24:J24) -> 0 | L24: =K24/6 -> 0
B26: HABILIDADE EM TREINAMENTO | C26: REFORÇADOR | D26: TENTATIVAS | E26: 1 | F26: 2 | G26: 3 | H26: 4 | I26: 5 | J26: 6 | K26: TOTAL | L26: % | M26: OBSERVAÇÕES
B27: Aceitar o fim da brincadeira sem chorar | D27: I | K27: =SUM(E27:J27) -> 0 | L27: =K27/6 -> 0
D28: P | K28: =SUM(E28:J28) -> 0 | L28: =K28/6 -> 0
D29: T | K29: =SUM(E29:J29) -> 0 | L29: =K29/6 -> 0

Sheet DIA 10
C2: PROTOCOLO DE APLICAÇÃO E REGISTRO | D2: TREINO
E3: DATA
D4: LEGENDA | F4: I = Resposta sem ajuda (independente) P = Resposta com ajuda parcial T = Resposta com ajuda total
B6: HABILIDADE EM TREINAMENTO | C6: REFORÇADOR | D6: TENTATIVAS | E6: 1 | F6: 2 | G6: 3 | H6: 4 | I6: 5 | J6: 6 | K6: TOTAL | L6: % | M6: OBSERVAÇÕES
B7: Seguir as regras do jogo | D7: I | K7: =SUM(E7:J7) -> 0 | L7: =K7/6 -> 0
D8: P | K8: =SUM(E8:J8) -> 0 | L8: =K8/6 -> 0
D9: T | K9: =SUM(E9:J9) -> 0 | L9: =K9/6 -> 0
B11: HABILIDADE EM TREINAMENTO | C11: REFORÇADOR | D11: TENTATIVAS | E11: 1 | F11: 2 | G11: 3 | H11: 4 | I11: 5 | J11: 6 | K11: TOTAL | L11: % | M11: OBSERVAÇÕES
B12: Esperar a sua vez | D12: I | K12: =SUM(E12:J12) -> 0 | L12: =K12/6 -> 0
D13: P | K13: =SUM(E13:J13) -> 0 | L13: =K13/6 -> 0
D14: T | K14: =SUM(E14:J14) -> 0 | L14: =K14/6 -> 0
B16: HABILIDADE EM TREINAMENTO | C16: REFORÇADOR | D16: TENTATIVAS | E16: 1 | F16: 2 | G16: 3 | H16: 4 | I16: 5 | J16: 6 | K16: TOTAL | L16: % | M16: OBSERVAÇÕES
B17: Lidar com frustração de perder | D17: I | K17: =SUM(E17:J17) -> 0 | L17: =K17/6 -> 0
D18: P | K18: =SUM(E18:J18) -> 0 | L18: =K18/6 -> 0
D19: T | K19: =SUM(E19:J19) -> 0 | L19: =K19/6 -> 0
B21: HABILIDADE EM TREINAMENTO | C21: REFORÇADOR | D21: TENTATIVAS | E21: 1 | F21: 2 | G21: 3 | H21: 4 | I21: 5 | J21: 6 | K21: TOTAL | L21: % | M21: OBSERVAÇÕES
B22: Permanecer no jogo até o final | D22: I | K22: =SUM(E22:J22) -> 0 | L22: =K22/6 -> 0
D23: P | K23: =SUM(E23:J23) -> 0 | L23: =K23/6 -> 0
D24: T | K24: =SUM(E24:J24) -> 0 | L24: =K24/6 -> 0
B26: HABILIDADE EM TREINAMENTO | C26: REFORÇADOR | D26: TENTATIVAS | E26: 1 | F26: 2 | G26: 3 | H26: 4 | I26: 5 | J26: 6 | K26: TOTAL | L26: % | M26: OBSERVAÇÕES
B27: Aceitar o fim da brincadeira sem chorar | D27: I | K27: =SUM(E27:J27) -> 0 | L27: =K27/6 -> 0
D28: P | K28: =SUM(E28:J28) -> 0 | L28: =K28/6 -> 0
D29: T | K29: =SUM(E29:J29) -> 0 | L29: =K29/6 -> 0

Sheet DIA 11
C2: PROTOCOLO DE APLICAÇÃO E REGISTRO | D2: TREINO
E3: DATA
D4: LEGENDA | F4: I = Resposta sem ajuda (independente) P = Resposta com ajuda parcial T = Resposta com ajuda total
B6: HABILIDADE EM TREINAMENTO | C6: REFORÇADOR | D6: TENTATIVAS | E6: 1 | F6: 2 | G6: 3 | H6: 4 | I6: 5 | J6: 6 | K6: TOTAL | L6: % | M6: OBSERVAÇÕES
B7: Seguir as regras do jogo | D7: I | K7: =SUM(E7:J7) -> 0 | L7: =K7/6 -> 0
D8: P | K8: =SUM(E8:J8) -> 0 | L8: =K8/6 -> 0
D9: T | K9: =SUM(E9:J9) -> 0 | L9: =K9/6 -> 0
B11: HABILIDADE EM TREINAMENTO | C11: REFORÇADOR | D11: TENTATIVAS | E11: 1 | F11: 2 | G11: 3 | H11: 4 | I11: 5 | J11: 6 | K11: TOTAL | L11: % | M11: OBSERVAÇÕES
B12: Esperar a sua vez | D12: I | K12: =SUM(E12:J12) -> 0 | L12: =K12/6 -> 0
D13: P | K13: =SUM(E13:J13) -> 0 | L13: =K13/6 -> 0
D14: T | K14: =SUM(E14:J14) -> 0 | L14: =K14/6 -> 0
B16: HABILIDADE EM TREINAMENTO | C16: REFORÇADOR | D16: TENTATIVAS | E16: 1 | F16: 2 | G16: 3 | H16: 4 | I16: 5 | J16: 6 | K16: TOTAL | L16: % | M16: OBSERVAÇÕES
B17: Lidar com frustração de perder | D17: I | K17: =SUM(E17:J17) -> 0 | L17: =K17/6 -> 0
D18: P | K18: =SUM(E18:J18) -> 0 | L18: =K18/6 -> 0
D19: T | K19: =SUM(E19:J19) -> 0 | L19: =K19/6 -> 0
B21: HABILIDADE EM TREINAMENTO | C21: REFORÇADOR | D21: TENTATIVAS | E21: 1 | F21: 2 | G21: 3 | H21: 4 | I21: 5 | J21: 6 | K21: TOTAL | L21: % | M21: OBSERVAÇÕES
B22: Permanecer no jogo até o final | D22: I | K22: =SUM(E22:J22) -> 0 | L22: =K22/6 -> 0
D23: P | K23: =SUM(E23:J23) -> 0 | L23: =K23/6 -> 0
D24: T | K24: =SUM(E24:J24) -> 0 | L24: =K24/6 -> 0
B26: HABILIDADE EM TREINAMENTO | C26: REFORÇADOR | D26: TENTATIVAS | E26: 1 | F26: 2 | G26: 3 | H26: 4 | I26: 5 | J26: 6 | K26: TOTAL | L26: % | M26: OBSERVAÇÕES
B27: Aceitar o fim da brincadeira sem chorar | D27: I | K27: =SUM(E27:J27) -> 0 | L27: =K27/6 -> 0
D28: P | K28: =SUM(E28:J28) -> 0 | L28: =K28/6 -> 0
D29: T | K29: =SUM(E29:J29) -> 0 | L29: =K29/6 -> 0

Sheet DIA 12
C2: PROTOCOLO DE APLICAÇÃO E REGISTRO | D2: TREINO
E3: DATA
D4: LEGENDA | F4: I = Resposta sem ajuda (independente) P = Resposta com ajuda parcial T = Resposta com ajuda total
B6: HABILIDADE EM TREINAMENTO | C6: REFORÇADOR | D6: TENTATIVAS | E6: 1 | F6: 2 | G6: 3 | H6: 4 | I6: 5 | J6: 6 | K6: TOTAL | L6: % | M6: OBSERVAÇÕES
B7: Seguir as regras do jogo | D7: I | K7: =SUM(E7:J7) -> 0 | L7: =K7/6 -> 0
D8: P | K8: =SUM(E8:J8) -> 0 | L8: =K8/6 -> 0
D9: T | K9: =SUM(E9:J9) -> 0 | L9: =K9/6 -> 0
B11: HABILIDADE EM TREINAMENTO | C11: REFORÇADOR | D11: TENTATIVAS | E11: 1 | F11: 2 | G11: 3 | H11: 4 | I11: 5 | J11: 6 | K11: TOTAL | L11: % | M11: OBSERVAÇÕES
B12: Esperar a sua vez | D12: I | K12: =SUM(E12:J12) -> 0 | L12: =K12/6 -> 0
D13: P | K13: =SUM(E13:J13) -> 0 | L13: =K13/6 -> 0
D14: T | K14: =SUM(E14:J14) -> 0 | L14: =K14/6 -> 0
B16: HABILIDADE EM TREINAMENTO | C16: REFORÇADOR | D16: TENTATIVAS | E16: 1 | F16: 2 | G16: 3 | H16: 4 | I16: 5 | J16: 6 | K16: TOTAL | L16: % | M16: OBSERVAÇÕES
B17: Lidar com frustração de perder | D17: I | K17: =SUM(E17:J17) -> 0 | L17: =K17/6 -> 0
D18: P | K18: =SUM(E18:J18) -> 0 | L18: =K18/6 -> 0
D19: T | K19: =SUM(E19:J19) -> 0 | L19: =K19/6 -> 0
B21: HABILIDADE EM TREINAMENTO | C21: REFORÇADOR | D21: TENTATIVAS | E21: 1 | F21: 2 | G21: 3 | H21: 4 | I21: 5 | J21: 6 | K21: TOTAL | L21: % | M21: OBSERVAÇÕES
B22: Permanecer no jogo até o final | D22: I | K22: =SUM(E22:J22) -> 0 | L22: =K22/6 -> 0
D23: P | K23: =SUM(E23:J23) -> 0 | L23: =K23/6 -> 0
D24: T | K24: =SUM(E24:J24) -> 0 | L24: =K24/6 -> 0
B26: HABILIDADE EM TREINAMENTO | C26: REFORÇADOR | D26: TENTATIVAS | E26: 1 | F26: 2 | G26: 3 | H26: 4 | I26: 5 | J26: 6 | K26: TOTAL | L26: % | M26: OBSERVAÇÕES
B27: Aceitar o fim da brincadeira sem chorar | D27: I | K27: =SUM(E27:J27) -> 0 | L27: =K27/6 -> 0
D28: P | K28: =SUM(E28:J28) -> 0 | L28: =K28/6 -> 0
D29: T | K29: =SUM(E29:J29) -> 0 | L29: =K29/6 -> 0

Sheet DIA 13
C2: PROTOCOLO DE APLICAÇÃO E REGISTRO | D2: TREINO
E3: DATA
D4: LEGENDA | F4: I = Resposta sem ajuda (independente) P = Resposta com ajuda parcial T = Resposta com ajuda total
B6: HABILIDADE EM TREINAMENTO | C6: REFORÇADOR | D6: TENTATIVAS | E6: 1 | F6: 2 | G6: 3 | H6: 4 | I6: 5 | J6: 6 | K6: TOTAL | L6: % | M6: OBSERVAÇÕES
B7: Seguir as regras do jogo | D7: I | K7: =SUM(E7:J7) -> 0 | L7: =K7/6 -> 0
D8: P | K8: =SUM(E8:J8) -> 0 | L8: =K8/6 -> 0
D9: T | K9: =SUM(E9:J9) -> 0 | L9: =K9/6 -> 0
B11: HABILIDADE EM TREINAMENTO | C11: REFORÇADOR | D11: TENTATIVAS | E11: 1 | F11: 2 | G11: 3 | H11: 4 | I11: 5 | J11: 6 | K11: TOTAL | L11: % | M11: OBSERVAÇÕES
B12: Esperar a sua vez | D12: I | K12: =SUM(E12:J12) -> 0 | L12: =K12/6 -> 0
D13: P | K13: =SUM(E13:J13) -> 0 | L13: =K13/6 -> 0
D14: T | K14: =SUM(E14:J14) -> 0 | L14: =K14/6 -> 0
B16: HABILIDADE EM TREINAMENTO | C16: REFORÇADOR | D16: TENTATIVAS | E16: 1 | F16: 2 | G16: 3 | H16: 4 | I16: 5 | J16: 6 | K16: TOTAL | L16: % | M16: OBSERVAÇÕES
B17: Lidar com frustração de perder | D17: I | K17: =SUM(E17:J17) -> 0 | L17: =K17/6 -> 0
D18: P | K18: =SUM(E18:J18) -> 0 | L18: =K18/6 -> 0
D19: T | K19: =SUM(E19:J19) -> 0 | L19: =K19/6 -> 0
B21: HABILIDADE EM TREINAMENTO | C21: REFORÇADOR | D21: TENTATIVAS | E21: 1 | F21: 2 | G21: 3 | H21: 4 | I21: 5 | J21: 6 | K21: TOTAL | L21: % | M21: OBSERVAÇÕES
B22: Permanecer no jogo até o final | D22: I | K22: =SUM(E22:J22) -> 0 | L22: =K22/6 -> 0
D23: P | K23: =SUM(E23:J23) -> 0 | L23: =K23/6 -> 0
D24: T | K24: =SUM(E24:J24) -> 0 | L24: =K24/6 -> 0
B26: HABILIDADE EM TREINAMENTO | C26: REFORÇADOR | D26: TENTATIVAS | E26: 1 | F26: 2 | G26: 3 | H26: 4 | I26: 5 | J26: 6 | K26: TOTAL | L26: % | M26: OBSERVAÇÕES
B27: Aceitar o fim da brincadeira sem chorar | D27: I | K27: =SUM(E27:J27) -> 0 | L27: =K27/6 -> 0
D28: P | K28: =SUM(E28:J28) -> 0 | L28: =K28/6 -> 0
D29: T | K29: =SUM(E29:J29) -> 0 | L29: =K29/6 -> 0

Sheet DIA 14
C2: PROTOCOLO DE APLICAÇÃO E REGISTRO | D2: TREINO
E3: DATA
D4: LEGENDA | F4: I = Resposta sem ajuda (independente) P = Resposta com ajuda parcial T = Resposta com ajuda total
B6: HABILIDADE EM TREINAMENTO | C6: REFORÇADOR | D6: TENTATIVAS | E6: 1 | F6: 2 | G6: 3 | H6: 4 | I6: 5 | J6: 6 | K6: TOTAL | L6: % | M6: OBSERVAÇÕES
B7: Seguir as regras do jogo | D7: I | K7: =SUM(E7:J7) -> 0 | L7: =K7/6 -> 0
D8: P | K8: =SUM(E8:J8) -> 0 | L8: =K8/6 -> 0
D9: T | K9: =SUM(E9:J9) -> 0 | L9: =K9/6 -> 0
B11: HABILIDADE EM TREINAMENTO | C11: REFORÇADOR | D11: TENTATIVAS | E11: 1 | F11: 2 | G11: 3 | H11: 4 | I11: 5 | J11: 6 | K11: TOTAL | L11: % | M11: OBSERVAÇÕES
B12: Esperar a sua vez | D12: I | K12: =SUM(E12:J12) -> 0 | L12: =K12/6 -> 0
D13: P | K13: =SUM(E13:J13) -> 0 | L13: =K13/6 -> 0
D14: T | K14: =SUM(E14:J14) -> 0 | L14: =K14/6 -> 0
B16: HABILIDADE EM TREINAMENTO | C16: REFORÇADOR | D16: TENTATIVAS | E16: 1 | F16: 2 | G16: 3 | H16: 4 | I16: 5 | J16: 6 | K16: TOTAL | L16: % | M16: OBSERVAÇÕES
B17: Lidar com frustração de perder | D17: I | K17: =SUM(E17:J17) -> 0 | L17: =K17/6 -> 0
D18: P | K18: =SUM(E18:J18) -> 0 | L18: =K18/6 -> 0
D19: T | K19: =SUM(E19:J19) -> 0 | L19: =K19/6 -> 0
B21: HABILIDADE EM TREINAMENTO | C21: REFORÇADOR | D21: TENTATIVAS | E21: 1 | F21: 2 | G21: 3 | H21: 4 | I21: 5 | J21: 6 | K21: TOTAL | L21: % | M21: OBSERVAÇÕES
B22: Permanecer no jogo até o final | D22: I | K22: =SUM(E22:J22) -> 0 | L22: =K22/6 -> 0
D23: P | K23: =SUM(E23:J23) -> 0 | L23: =K23/6 -> 0
D24: T | K24: =SUM(E24:J24) -> 0 | L24: =K24/6 -> 0
B26: HABILIDADE EM TREINAMENTO | C26: REFORÇADOR | D26: TENTATIVAS | E26: 1 | F26: 2 | G26: 3 | H26: 4 | I26: 5 | J26: 6 | K26: TOTAL | L26: % | M26: OBSERVAÇÕES
B27: Aceitar o fim da brincadeira sem chorar | D27: I | K27: =SUM(E27:J27) -> 0 | L27: =K27/6 -> 0
D28: P | K28: =SUM(E28:J28) -> 0 | L28: =K28/6 -> 0
D29: T | K29: =SUM(E29:J29) -> 0 | L29: =K29/6 -> 0

Sheet DIA 15
C2: PROTOCOLO DE APLICAÇÃO E REGISTRO | D2: TREINO
E3: DATA
D4: LEGENDA | F4: I = Resposta sem ajuda (independente) P = Resposta com ajuda parcial T = Resposta com ajuda total
B6: HABILIDADE EM TREINAMENTO | C6: REFORÇADOR | D6: TENTATIVAS | E6: 1 | F6: 2 | G6: 3 | H6: 4 | I6: 5 | J6: 6 | K6: TOTAL | L6: % | M6: OBSERVAÇÕES
B7: Seguir as regras do jogo | D7: I | K7: =SUM(E7:J7) -> 0 | L7: =K7/6 -> 0
D8: P | K8: =SUM(E8:J8) -> 0 | L8: =K8/6 -> 0
D9: T | K9: =SUM(E9:J9) -> 0 | L9: =K9/6 -> 0
B11: HABILIDADE EM TREINAMENTO | C11: REFORÇADOR | D11: TENTATIVAS | E11: 1 | F11: 2 | G11: 3 | H11: 4 | I11: 5 | J11: 6 | K11: TOTAL | L11: % | M11: OBSERVAÇÕES
B12: Esperar a sua vez | D12: I | K12: =SUM(E12:J12) -> 0 | L12: =K12/6 -> 0
D13: P | K13: =SUM(E13:J13) -> 0 | L13: =K13/6 -> 0
D14: T | K14: =SUM(E14:J14) -> 0 | L14: =K14/6 -> 0
B16: HABILIDADE EM TREINAMENTO | C16: REFORÇADOR | D16: TENTATIVAS | E16: 1 | F16: 2 | G16: 3 | H16: 4 | I16: 5 | J16: 6 | K16: TOTAL | L16: % | M16: OBSERVAÇÕES
B17: Lidar com frustração de perder | D17: I | K17: =SUM(E17:J17) -> 0 | L17: =K17/6 -> 0
D18: P | K18: =SUM(E18:J18) -> 0 | L18: =K18/6 -> 0
D19: T | K19: =SUM(E19:J19) -> 0 | L19: =K19/6 -> 0
B21: HABILIDADE EM TREINAMENTO | C21: REFORÇADOR | D21: TENTATIVAS | E21: 1 | F21: 2 | G21: 3 | H21: 4 | I21: 5 | J21: 6 | K21: TOTAL | L21: % | M21: OBSERVAÇÕES
B22: Permanecer no jogo até o final | D22: I | K22: =SUM(E22:J22) -> 0 | L22: =K22/6 -> 0
D23: P | K23: =SUM(E23:J23) -> 0 | L23: =K23/6 -> 0
D24: T | K24: =SUM(E24:J24) -> 0 | L24: =K24/6 -> 0
B26: HABILIDADE EM TREINAMENTO | C26: REFORÇADOR | D26: TENTATIVAS | E26: 1 | F26: 2 | G26: 3 | H26: 4 | I26: 5 | J26: 6 | K26: TOTAL | L26: % | M26: OBSERVAÇÕES
B27: Aceitar o fim da brincadeira sem chorar | D27: I | K27: =SUM(E27:J27) -> 0 | L27: =K27/6 -> 0
D28: P | K28: =SUM(E28:J28) -> 0 | L28: =K28/6 -> 0
D29: T | K29: =SUM(E29:J29) -> 0 | L29: =K29/6 -> 0

Sheet DIA 16
C2: PROTOCOLO DE APLICAÇÃO E REGISTRO | D2: TREINO
E3: DATA
D4: LEGENDA | F4: I = Resposta sem ajuda (independente) P = Resposta com ajuda parcial T = Resposta com ajuda total
B6: HABILIDADE EM TREINAMENTO | C6: REFORÇADOR | D6: TENTATIVAS | E6: 1 | F6: 2 | G6: 3 | H6: 4 | I6: 5 | J6: 6 | K6: TOTAL | L6: % | M6: OBSERVAÇÕES
B7: Seguir as regras do jogo | D7: I | K7: =SUM(E7:J7) -> 0 | L7: =K7/6 -> 0
D8: P | K8: =SUM(E8:J8) -> 0 | L8: =K8/6 -> 0
D9: T | K9: =SUM(E9:J9) -> 0 | L9: =K9/6 -> 0
B11: HABILIDADE EM TREINAMENTO | C11: REFORÇADOR | D11: TENTATIVAS | E11: 1 | F11: 2 | G11: 3 | H11: 4 | I11: 5 | J11: 6 | K11: TOTAL | L11: % | M11: OBSERVAÇÕES
B12: Esperar a sua vez | D12: I | K12: =SUM(E12:J12) -> 0 | L12: =K12/6 -> 0
D13: P | K13: =SUM(E13:J13) -> 0 | L13: =K13/6 -> 0
D14: T | K14: =SUM(E14:J14) -> 0 | L14: =K14/6 -> 0
B16: HABILIDADE EM TREINAMENTO | C16: REFORÇADOR | D16: TENTATIVAS | E16: 1 | F16: 2 | G16: 3 | H16: 4 | I16: 5 | J16: 6 | K16: TOTAL | L16: % | M16: OBSERVAÇÕES
B17: Lidar com frustração de perder | D17: I | K17: =SUM(E17:J17) -> 0 | L17: =K17/6 -> 0
D18: P | K18: =SUM(E18:J18) -> 0 | L18: =K18/6 -> 0
D19: T | K19: =SUM(E19:J19) -> 0 | L19: =K19/6 -> 0
B21: HABILIDADE EM TREINAMENTO | C21: REFORÇADOR | D21: TENTATIVAS | E21: 1 | F21: 2 | G21: 3 | H21: 4 | I21: 5 | J21: 6 | K21: TOTAL | L21: % | M21: OBSERVAÇÕES
B22: Permanecer no jogo até o final | D22: I | K22: =SUM(E22:J22) -> 0 | L22: =K22/6 -> 0
D23: P | K23: =SUM(E23:J23) -> 0 | L23: =K23/6 -> 0
D24: T | K24: =SUM(E24:J24) -> 0 | L24: =K24/6 -> 0
B26: HABILIDADE EM TREINAMENTO | C26: REFORÇADOR | D26: TENTATIVAS | E26: 1 | F26: 2 | G26: 3 | H26: 4 | I26: 5 | J26: 6 | K26: TOTAL | L26: % | M26: OBSERVAÇÕES
B27: Aceitar o fim da brincadeira sem chorar | D27: I | K27: =SUM(E27:J27) -> 0 | L27: =K27/6 -> 0
D28: P | K28: =SUM(E28:J28) -> 0 | L28: =K28/6 -> 0
D29: T | K29: =SUM(E29:J29) -> 0 | L29: =K29/6 -> 0

Sheet DIA 17
C2: PROTOCOLO DE APLICAÇÃO E REGISTRO | D2: TREINO
E3: DATA
D4: LEGENDA | F4: I = Resposta sem ajuda (independente) P = Resposta com ajuda parcial T = Resposta com ajuda total
B6: HABILIDADE EM TREINAMENTO | C6: REFORÇADOR | D6: TENTATIVAS | E6: 1 | F6: 2 | G6: 3 | H6: 4 | I6: 5 | J6: 6 | K6: TOTAL | L6: % | M6: OBSERVAÇÕES
B7: Seguir as regras do jogo | D7: I | K7: =SUM(E7:J7) -> 0 | L7: =K7/6 -> 0
D8: P | K8: =SUM(E8:J8) -> 0 | L8: =K8/6 -> 0
D9: T | K9: =SUM(E9:J9) -> 0 | L9: =K9/6 -> 0
B11: HABILIDADE EM TREINAMENTO | C11: REFORÇADOR | D11: TENTATIVAS | E11: 1 | F11: 2 | G11: 3 | H11: 4 | I11: 5 | J11: 6 | K11: TOTAL | L11: % | M11: OBSERVAÇÕES
B12: Esperar a sua vez | D12: I | K12: =SUM(E12:J12) -> 0 | L12: =K12/6 -> 0
D13: P | K13: =SUM(E13:J13) -> 0 | L13: =K13/6 -> 0
D14: T | K14: =SUM(E14:J14) -> 0 | L14: =K14/6 -> 0
B16: HABILIDADE EM TREINAMENTO | C16: REFORÇADOR | D16: TENTATIVAS | E16: 1 | F16: 2 | G16: 3 | H16: 4 | I16: 5 | J16: 6 | K16: TOTAL | L16: % | M16: OBSERVAÇÕES
B17: Lidar com frustração de perder | D17: I | K17: =SUM(E17:J17) -> 0 | L17: =K17/6 -> 0
D18: P | K18: =SUM(E18:J18) -> 0 | L18: =K18/6 -> 0
D19: T | K19: =SUM(E19:J19) -> 0 | L19: =K19/6 -> 0
B21: HABILIDADE EM TREINAMENTO | C21: REFORÇADOR | D21: TENTATIVAS | E21: 1 | F21: 2 | G21: 3 | H21: 4 | I21: 5 | J21: 6 | K21: TOTAL | L21: % | M21: OBSERVAÇÕES
B22: Permanecer no jogo até o final | D22: I | K22: =SUM(E22:J22) -> 0 | L22: =K22/6 -> 0
D23: P | K23: =SUM(E23:J23) -> 0 | L23: =K23/6 -> 0
D24: T | K24: =SUM(E24:J24) -> 0 | L24: =K24/6 -> 0
B26: HABILIDADE EM TREINAMENTO | C26: REFORÇADOR | D26: TENTATIVAS | E26: 1 | F26: 2 | G26: 3 | H26: 4 | I26: 5 | J26: 6 | K26: TOTAL | L26: % | M26: OBSERVAÇÕES
B27: Aceitar o fim da brincadeira sem chorar | D27: I | K27: =SUM(E27:J27) -> 0 | L27: =K27/6 -> 0
D28: P | K28: =SUM(E28:J28) -> 0 | L28: =K28/6 -> 0
D29: T | K29: =SUM(E29:J29) -> 0 | L29: =K29/6 -> 0

Sheet DIA 18
C2: PROTOCOLO DE APLICAÇÃO E REGISTRO | D2: TREINO
E3: DATA
D4: LEGENDA | F4: I = Resposta sem ajuda (independente) P = Resposta com ajuda parcial T = Resposta com ajuda total
B6: HABILIDADE EM TREINAMENTO | C6: REFORÇADOR | D6: TENTATIVAS | E6: 1 | F6: 2 | G6: 3 | H6: 4 | I6: 5 | J6: 6 | K6: TOTAL | L6: % | M6: OBSERVAÇÕES
B7: Seguir as regras do jogo | D7: I | K7: =SUM(E7:J7) -> 0 | L7: =K7/6 -> 0
D8: P | K8: =SUM(E8:J8) -> 0 | L8: =K8/6 -> 0
D9: T | K9: =SUM(E9:J9) -> 0 | L9: =K9/6 -> 0
B11: HABILIDADE EM TREINAMENTO | C11: REFORÇADOR | D11: TENTATIVAS | E11: 1 | F11: 2 | G11: 3 | H11: 4 | I11: 5 | J11: 6 | K11: TOTAL | L11: % | M11: OBSERVAÇÕES
B12: Esperar a sua vez | D12: I | K12: =SUM(E12:J12) -> 0 | L12: =K12/6 -> 0
D13: P | K13: =SUM(E13:J13) -> 0 | L13: =K13/6 -> 0
D14: T | K14: =SUM(E14:J14) -> 0 | L14: =K14/6 -> 0
B16: HABILIDADE EM TREINAMENTO | C16: REFORÇADOR | D16: TENTATIVAS | E16: 1 | F16: 2 | G16: 3 | H16: 4 | I16: 5 | J16: 6 | K16: TOTAL | L16: % | M16: OBSERVAÇÕES
B17: Lidar com frustração de perder | D17: I | K17: =SUM(E17:J17) -> 0 | L17: =K17/6 -> 0
D18: P | K18: =SUM(E18:J18) -> 0 | L18: =K18/6 -> 0
D19: T | K19: =SUM(E19:J19) -> 0 | L19: =K19/6 -> 0
B21: HABILIDADE EM TREINAMENTO | C21: REFORÇADOR | D21: TENTATIVAS | E21: 1 | F21: 2 | G21: 3 | H21: 4 | I21: 5 | J21: 6 | K21: TOTAL | L21: % | M21: OBSERVAÇÕES
B22: Permanecer no jogo até o final | D22: I | K22: =SUM(E22:J22) -> 0 | L22: =K22/6 -> 0
D23: P | K23: =SUM(E23:J23) -> 0 | L23: =K23/6 -> 0
D24: T | K24: =SUM(E24:J24) -> 0 | L24: =K24/6 -> 0
B26: HABILIDADE EM TREINAMENTO | C26: REFORÇADOR | D26: TENTATIVAS | E26: 1 | F26: 2 | G26: 3 | H26: 4 | I26: 5 | J26: 6 | K26: TOTAL | L26: % | M26: OBSERVAÇÕES
B27: Aceitar o fim da brincadeira sem chorar | D27: I | K27: =SUM(E27:J27) -> 0 | L27: =K27/6 -> 0
D28: P | K28: =SUM(E28:J28) -> 0 | L28: =K28/6 -> 0
D29: T | K29: =SUM(E29:J29) -> 0 | L29: =K29/6 -> 0

Sheet DIA 19
C2: PROTOCOLO DE APLICAÇÃO E REGISTRO | D2: TREINO
E3: DATA
D4: LEGENDA | F4: I = Resposta sem ajuda (independente) P = Resposta com ajuda parcial T = Resposta com ajuda total
B6: HABILIDADE EM TREINAMENTO | C6: REFORÇADOR | D6: TENTATIVAS | E6: 1 | F6: 2 | G6: 3 | H6: 4 | I6: 5 | J6: 6 | K6: TOTAL | L6: % | M6: OBSERVAÇÕES
B7: Seguir as regras do jogo | D7: I | K7: =SUM(E7:J7) -> 0 | L7: =K7/6 -> 0
D8: P | K8: =SUM(E8:J8) -> 0 | L8: =K8/6 -> 0
D9: T | K9: =SUM(E9:J9) -> 0 | L9: =K9/6 -> 0
B11: HABILIDADE EM TREINAMENTO | C11: REFORÇADOR | D11: TENTATIVAS | E11: 1 | F11: 2 | G11: 3 | H11: 4 | I11: 5 | J11: 6 | K11: TOTAL | L11: % | M11: OBSERVAÇÕES
B12: Esperar a sua vez | D12: I | K12: =SUM(E12:J12) -> 0 | L12: =K12/6 -> 0
D13: P | K13: =SUM(E13:J13) -> 0 | L13: =K13/6 -> 0
D14: T | K14: =SUM(E14:J14) -> 0 | L14: =K14/6 -> 0
B16: HABILIDADE EM TREINAMENTO | C16: REFORÇADOR | D16: TENTATIVAS | E16: 1 | F16: 2 | G16: 3 | H16: 4 | I16: 5 | J16: 6 | K16: TOTAL | L16: % | M16: OBSERVAÇÕES
B17: Lidar com frustração de perder | D17: I | K17: =SUM(E17:J17) -> 0 | L17: =K17/6 -> 0
D18: P | K18: =SUM(E18:J18) -> 0 | L18: =K18/6 -> 0
D19: T | K19: =SUM(E19:J19) -> 0 | L19: =K19/6 -> 0
B21: HABILIDADE EM TREINAMENTO | C21: REFORÇADOR | D21: TENTATIVAS | E21: 1 | F21: 2 | G21: 3 | H21: 4 | I21: 5 | J21: 6 | K21: TOTAL | L21: % | M21: OBSERVAÇÕES
B22: Permanecer no jogo até o final | D22: I | K22: =SUM(E22:J22) -> 0 | L22: =K22/6 -> 0
D23: P | K23: =SUM(E23:J23) -> 0 | L23: =K23/6 -> 0
D24: T | K24: =SUM(E24:J24) -> 0 | L24: =K24/6 -> 0
B26: HABILIDADE EM TREINAMENTO | C26: REFORÇADOR | D26: TENTATIVAS | E26: 1 | F26: 2 | G26: 3 | H26: 4 | I26: 5 | J26: 6 | K26: TOTAL | L26: % | M26: OBSERVAÇÕES
B27: Aceitar o fim da brincadeira sem chorar | D27: I | K27: =SUM(E27:J27) -> 0 | L27: =K27/6 -> 0
D28: P | K28: =SUM(E28:J28) -> 0 | L28: =K28/6 -> 0
D29: T | K29: =SUM(E29:J29) -> 0 | L29: =K29/6 -> 0

Sheet DIA 20
C2: PROTOCOLO DE APLICAÇÃO E REGISTRO | D2: TREINO
E3: DATA
D4: LEGENDA | F4: I = Resposta sem ajuda (independente) P = Resposta com ajuda parcial T = Resposta com ajuda total
B6: HABILIDADE EM TREINAMENTO | C6: REFORÇADOR | D6: TENTATIVAS | E6: 1 | F6: 2 | G6: 3 | H6: 4 | I6: 5 | J6: 6 | K6: TOTAL | L6: % | M6: OBSERVAÇÕES
B7: Seguir as regras do jogo | D7: I | K7: =SUM(E7:J7) -> 0 | L7: =K7/6 -> 0
D8: P | K8: =SUM(E8:J8) -> 0 | L8: =K8/6 -> 0
D9: T | K9: =SUM(E9:J9) -> 0 | L9: =K9/6 -> 0
B11: HABILIDADE EM TREINAMENTO | C11: REFORÇADOR | D11: TENTATIVAS | E11: 1 | F11: 2 | G11: 3 | H11: 4 | I11: 5 | J11: 6 | K11: TOTAL | L11: % | M11: OBSERVAÇÕES
B12: Esperar a sua vez | D12: I | K12: =SUM(E12:J12) -> 0 | L12: =K12/6 -> 0
D13: P | K13: =SUM(E13:J13) -> 0 | L13: =K13/6 -> 0
D14: T | K14: =SUM(E14:J14) -> 0 | L14: =K14/6 -> 0
B16: HABILIDADE EM TREINAMENTO | C16: REFORÇADOR | D16: TENTATIVAS | E16: 1 | F16: 2 | G16: 3 | H16: 4 | I16: 5 | J16: 6 | K16: TOTAL | L16: % | M16: OBSERVAÇÕES
B17: Lidar com frustração de perder | D17: I | K17: =SUM(E17:J17) -> 0 | L17: =K17/6 -> 0
D18: P | K18: =SUM(E18:J18) -> 0 | L18: =K18/6 -> 0
D19: T | K19: =SUM(E19:J19) -> 0 | L19: =K19/6 -> 0
B21: HABILIDADE EM TREINAMENTO | C21: REFORÇADOR | D21: TENTATIVAS | E21: 1 | F21: 2 | G21: 3 | H21: 4 | I21: 5 | J21: 6 | K21: TOTAL | L21: % | M21: OBSERVAÇÕES
B22: Permanecer no jogo até o final | D22: I | K22: =SUM(E22:J22) -> 0 | L22: =K22/6 -> 0
D23: P | K23: =SUM(E23:J23) -> 0 | L23: =K23/6 -> 0
D24: T | K24: =SUM(E24:J24) -> 0 | L24: =K24/6 -> 0
B26: HABILIDADE EM TREINAMENTO | C26: REFORÇADOR | D26: TENTATIVAS | E26: 1 | F26: 2 | G26: 3 | H26: 4 | I26: 5 | J26: 6 | K26: TOTAL | L26: % | M26: OBSERVAÇÕES
B27: Aceitar o fim da brincadeira sem chorar | D27: I | K27: =SUM(E27:J27) -> 0 | L27: =K27/6 -> 0
D28: P | K28: =SUM(E28:J28) -> 0 | L28: =K28/6 -> 0
D29: T | K29: =SUM(E29:J29) -> 0 | L29: =K29/6 -> 0

Sheet DIA 21
C2: PROTOCOLO DE APLICAÇÃO E REGISTRO | D2: TREINO
E3: DATA
D4: LEGENDA | F4: I = Resposta sem ajuda (independente) P = Resposta com ajuda parcial T = Resposta com ajuda total
B6: HABILIDADE EM TREINAMENTO | C6: REFORÇADOR | D6: TENTATIVAS | E6: 1 | F6: 2 | G6: 3 | H6: 4 | I6: 5 | J6: 6 | K6: TOTAL | L6: % | M6: OBSERVAÇÕES
B7: Seguir as regras do jogo | D7: I | K7: =SUM(E7:J7) -> 0 | L7: =K7/6 -> 0
D8: P | K8: =SUM(E8:J8) -> 0 | L8: =K8/6 -> 0
D9: T | K9: =SUM(E9:J9) -> 0 | L9: =K9/6 -> 0
B11: HABILIDADE EM TREINAMENTO | C11: REFORÇADOR | D11: TENTATIVAS | E11: 1 | F11: 2 | G11: 3 | H11: 4 | I11: 5 | J11: 6 | K11: TOTAL | L11: % | M11: OBSERVAÇÕES
B12: Esperar a sua vez | D12: I | K12: =SUM(E12:J12) -> 0 | L12: =K12/6 -> 0
D13: P | K13: =SUM(E13:J13) -> 0 | L13: =K13/6 -> 0
D14: T | K14: =SUM(E14:J14) -> 0 | L14: =K14/6 -> 0
B16: HABILIDADE EM TREINAMENTO | C16: REFORÇADOR | D16: TENTATIVAS | E16: 1 | F16: 2 | G16: 3 | H16: 4 | I16: 5 | J16: 6 | K16: TOTAL | L16: % | M16: OBSERVAÇÕES
B17: Lidar com frustração de perder | D17: I | K17: =SUM(E17:J17) -> 0 | L17: =K17/6 -> 0
D18: P | K18: =SUM(E18:J18) -> 0 | L18: =K18/6 -> 0
D19: T | K19: =SUM(E19:J19) -> 0 | L19: =K19/6 -> 0
B21: HABILIDADE EM TREINAMENTO | C21: REFORÇADOR | D21: TENTATIVAS | E21: 1 | F21: 2 | G21: 3 | H21: 4 | I21: 5 | J21: 6 | K21: TOTAL | L21: % | M21: OBSERVAÇÕES
B22: Permanecer no jogo até o final | D22: I | K22: =SUM(E22:J22) -> 0 | L22: =K22/6 -> 0
D23: P | K23: =SUM(E23:J23) -> 0 | L23: =K23/6 -> 0
D24: T | K24: =SUM(E24:J24) -> 0 | L24: =K24/6 -> 0
B26: HABILIDADE EM TREINAMENTO | C26: REFORÇADOR | D26: TENTATIVAS | E26: 1 | F26: 2 | G26: 3 | H26: 4 | I26: 5 | J26: 6 | K26: TOTAL | L26: % | M26: OBSERVAÇÕES
B27: Aceitar o fim da brincadeira sem chorar | D27: I | K27: =SUM(E27:J27) -> 0 | L27: =K27/6 -> 0
D28: P | K28: =SUM(E28:J28) -> 0 | L28: =K28/6 -> 0
D29: T | K29: =SUM(E29:J29) -> 0 | L29: =K29/6 -> 0

Sheet DIA 22
C2: PROTOCOLO DE APLICAÇÃO E REGISTRO | D2: TREINO
E3: DATA
D4: LEGENDA | F4: I = Resposta sem ajuda (independente) P = Resposta com ajuda parcial T = Resposta com ajuda total
B6: HABILIDADE EM TREINAMENTO | C6: REFORÇADOR | D6: TENTATIVAS | E6: 1 | F6: 2 | G6: 3 | H6: 4 | I6: 5 | J6: 6 | K6: TOTAL | L6: % | M6: OBSERVAÇÕES
B7: Seguir as regras do jogo | D7: I | K7: =SUM(E7:J7) -> 0 | L7: =K7/6 -> 0
D8: P | K8: =SUM(E8:J8) -> 0 | L8: =K8/6 -> 0
D9: T | K9: =SUM(E9:J9) -> 0 | L9: =K9/6 -> 0
B11: HABILIDADE EM TREINAMENTO | C11: REFORÇADOR | D11: TENTATIVAS | E11: 1 | F11: 2 | G11: 3 | H11: 4 | I11: 5 | J11: 6 | K11: TOTAL | L11: % | M11: OBSERVAÇÕES
B12: Esperar a sua vez | D12: I | K12: =SUM(E12:J12) -> 0 | L12: =K12/6 -> 0
D13: P | K13: =SUM(E13:J13) -> 0 | L13: =K13/6 -> 0
D14: T | K14: =SUM(E14:J14) -> 0 | L14: =K14/6 -> 0
B16: HABILIDADE EM TREINAMENTO | C16: REFORÇADOR | D16: TENTATIVAS | E16: 1 | F16: 2 | G16: 3 | H16: 4 | I16: 5 | J16: 6 | K16: TOTAL | L16: % | M16: OBSERVAÇÕES
B17: Lidar com frustração de perder | D17: I | K17: =SUM(E17:J17) -> 0 | L17: =K17/6 -> 0
D18: P | K18: =SUM(E18:J18) -> 0 | L18: =K18/6 -> 0
D19: T | K19: =SUM(E19:J19) -> 0 | L19: =K19/6 -> 0
B21: HABILIDADE EM TREINAMENTO | C21: REFORÇADOR | D21: TENTATIVAS | E21: 1 | F21: 2 | G21: 3 | H21: 4 | I21: 5 | J21: 6 | K21: TOTAL | L21: % | M21: OBSERVAÇÕES
B22: Permanecer no jogo até o final | D22: I | K22: =SUM(E22:J22) -> 0 | L22: =K22/6 -> 0
D23: P | K23: =SUM(E23:J23) -> 0 | L23: =K23/6 -> 0
D24: T | K24: =SUM(E24:J24) -> 0 | L24: =K24/6 -> 0
B26: HABILIDADE EM TREINAMENTO | C26: REFORÇADOR | D26: TENTATIVAS | E26: 1 | F26: 2 | G26: 3 | H26: 4 | I26: 5 | J26: 6 | K26: TOTAL | L26: % | M26: OBSERVAÇÕES
B27: Aceitar o fim da brincadeira sem chorar | D27: I | K27: =SUM(E27:J27) -> 0 | L27: =K27/6 -> 0
D28: P | K28: =SUM(E28:J28) -> 0 | L28: =K28/6 -> 0
D29: T | K29: =SUM(E29:J29) -> 0 | L29: =K29/6 -> 0

Sheet DIA 23
C2: PROTOCOLO DE APLICAÇÃO E REGISTRO | D2: TREINO
E3: DATA
D4: LEGENDA | F4: I = Resposta sem ajuda (independente) P = Resposta com ajuda parcial T = Resposta com ajuda total
B6: HABILIDADE EM TREINAMENTO | C6: REFORÇADOR | D6: TENTATIVAS | E6: 1 | F6: 2 | G6: 3 | H6: 4 | I6: 5 | J6: 6 | K6: TOTAL | L6: % | M6: OBSERVAÇÕES
B7: Seguir as regras do jogo | D7: I | K7: =SUM(E7:J7) -> 0 | L7: =K7/6 -> 0
D8: P | K8: =SUM(E8:J8) -> 0 | L8: =K8/6 -> 0
D9: T | K9: =SUM(E9:J9) -> 0 | L9: =K9/6 -> 0
B11: HABILIDADE EM TREINAMENTO | C11: REFORÇADOR | D11: TENTATIVAS | E11: 1 | F11: 2 | G11: 3 | H11: 4 | I11: 5 | J11: 6 | K11: TOTAL | L11: % | M11: OBSERVAÇÕES
B12: Esperar a sua vez | D12: I | K12: =SUM(E12:J12) -> 0 | L12: =K12/6 -> 0
D13: P | K13: =SUM(E13:J13) -> 0 | L13: =K13/6 -> 0
D14: T | K14: =SUM(E14:J14) -> 0 | L14: =K14/6 -> 0
B16: HABILIDADE EM TREINAMENTO | C16: REFORÇADOR | D16: TENTATIVAS | E16: 1 | F16: 2 | G16: 3 | H16: 4 | I16: 5 | J16: 6 | K16: TOTAL | L16: % | M16: OBSERVAÇÕES
B17: Lidar com frustração de perder | D17: I | K17: =SUM(E17:J17) -> 0 | L17: =K17/6 -> 0
D18: P | K18: =SUM(E18:J18) -> 0 | L18: =K18/6 -> 0
D19: T | K19: =SUM(E19:J19) -> 0 | L19: =K19/6 -> 0
B21: HABILIDADE EM TREINAMENTO | C21: REFORÇADOR | D21: TENTATIVAS | E21: 1 | F21: 2 | G21: 3 | H21: 4 | I21: 5 | J21: 6 | K21: TOTAL | L21: % | M21: OBSERVAÇÕES
B22: Permanecer no jogo até o final | D22: I | K22: =SUM(E22:J22) -> 0 | L22: =K22/6 -> 0
D23: P | K23: =SUM(E23:J23) -> 0 | L23: =K23/6 -> 0
D24: T | K24: =SUM(E24:J24) -> 0 | L24: =K24/6 -> 0
B26: HABILIDADE EM TREINAMENTO | C26: REFORÇADOR | D26: TENTATIVAS | E26: 1 | F26: 2 | G26: 3 | H26: 4 | I26: 5 | J26: 6 | K26: TOTAL | L26: % | M26: OBSERVAÇÕES
B27: Aceitar o fim da brincadeira sem chorar | D27: I | K27: =SUM(E27:J27) -> 0 | L27: =K27/6 -> 0
D28: P | K28: =SUM(E28:J28) -> 0 | L28: =K28/6 -> 0
D29: T | K29: =SUM(E29:J29) -> 0 | L29: =K29/6 -> 0

Sheet DIA 24
C2: PROTOCOLO DE APLICAÇÃO E REGISTRO | D2: TREINO
E3: DATA
D4: LEGENDA | F4: I = Resposta sem ajuda (independente) P = Resposta com ajuda parcial T = Resposta com ajuda total
B6: HABILIDADE EM TREINAMENTO | C6: REFORÇADOR | D6: TENTATIVAS | E6: 1 | F6: 2 | G6: 3 | H6: 4 | I6: 5 | J6: 6 | K6: TOTAL | L6: % | M6: OBSERVAÇÕES
B7: Seguir as regras do jogo | D7: I | K7: =SUM(E7:J7) -> 0 | L7: =K7/6 -> 0
D8: P | K8: =SUM(E8:J8) -> 0 | L8: =K8/6 -> 0
D9: T | K9: =SUM(E9:J9) -> 0 | L9: =K9/6 -> 0
B11: HABILIDADE EM TREINAMENTO | C11: REFORÇADOR | D11: TENTATIVAS | E11: 1 | F11: 2 | G11: 3 | H11: 4 | I11: 5 | J11: 6 | K11: TOTAL | L11: % | M11: OBSERVAÇÕES
B12: Esperar a sua vez | D12: I | K12: =SUM(E12:J12) -> 0 | L12: =K12/6 -> 0
D13: P | K13: =SUM(E13:J13) -> 0 | L13: =K13/6 -> 0
D14: T | K14: =SUM(E14:J14) -> 0 | L14: =K14/6 -> 0
B16: HABILIDADE EM TREINAMENTO | C16: REFORÇADOR | D16: TENTATIVAS | E16: 1 | F16: 2 | G16: 3 | H16: 4 | I16: 5 | J16: 6 | K16: TOTAL | L16: % | M16: OBSERVAÇÕES
B17: Lidar com frustração de perder | D17: I | K17: =SUM(E17:J17) -> 0 | L17: =K17/6 -> 0
D18: P | K18: =SUM(E18:J18) -> 0 | L18: =K18/6 -> 0
D19: T | K19: =SUM(E19:J19) -> 0 | L19: =K19/6 -> 0
B21: HABILIDADE EM TREINAMENTO | C21: REFORÇADOR | D21: TENTATIVAS | E21: 1 | F21: 2 | G21: 3 | H21: 4 | I21: 5 | J21: 6 | K21: TOTAL | L21: % | M21: OBSERVAÇÕES
B22: Permanecer no jogo até o final | D22: I | K22: =SUM(E22:J22) -> 0 | L22: =K22/6 -> 0
D23: P | K23: =SUM(E23:J23) -> 0 | L23: =K23/6 -> 0
D24: T | K24: =SUM(E24:J24) -> 0 | L24: =K24/6 -> 0
B26: HABILIDADE EM TREINAMENTO | C26: REFORÇADOR | D26: TENTATIVAS | E26: 1 | F26: 2 | G26: 3 | H26: 4 | I26: 5 | J26: 6 | K26: TOTAL | L26: % | M26: OBSERVAÇÕES
B27: Aceitar o fim da brincadeira sem chorar | D27: I | K27: =SUM(E27:J27) -> 0 | L27: =K27/6 -> 0
D28: P | K28: =SUM(E28:J28) -> 0 | L28: =K28/6 -> 0
D29: T | K29: =SUM(E29:J29) -> 0 | L29: =K29/6 -> 0

Sheet DIA 25
C2: PROTOCOLO DE APLICAÇÃO E REGISTRO | D2: TREINO
E3: DATA
D4: LEGENDA | F4: I = Resposta sem ajuda (independente) P = Resposta com ajuda parcial T = Resposta com ajuda total
B6: HABILIDADE EM TREINAMENTO | C6: REFORÇADOR | D6: TENTATIVAS | E6: 1 | F6: 2 | G6: 3 | H6: 4 | I6: 5 | J6: 6 | K6: TOTAL | L6: % | M6: OBSERVAÇÕES
B7: Seguir as regras do jogo | D7: I | K7: =SUM(E7:J7) -> 0 | L7: =K7/6 -> 0
D8: P | K8: =SUM(E8:J8) -> 0 | L8: =K8/6 -> 0
D9: T | K9: =SUM(E9:J9) -> 0 | L9: =K9/6 -> 0
B11: HABILIDADE EM TREINAMENTO | C11: REFORÇADOR | D11: TENTATIVAS | E11: 1 | F11: 2 | G11: 3 | H11: 4 | I11: 5 | J11: 6 | K11: TOTAL | L11: % | M11: OBSERVAÇÕES
B12: Esperar a sua vez | D12: I | K12: =SUM(E12:J12) -> 0 | L12: =K12/6 -> 0
D13: P | K13: =SUM(E13:J13) -> 0 | L13: =K13/6 -> 0
D14: T | K14: =SUM(E14:J14) -> 0 | L14: =K14/6 -> 0
B16: HABILIDADE EM TREINAMENTO | C16: REFORÇADOR | D16: TENTATIVAS | E16: 1 | F16: 2 | G16: 3 | H16: 4 | I16: 5 | J16: 6 | K16: TOTAL | L16: % | M16: OBSERVAÇÕES
B17: Lidar com frustração de perder | D17: I | K17: =SUM(E17:J17) -> 0 | L17: =K17/6 -> 0
D18: P | K18: =SUM(E18:J18) -> 0 | L18: =K18/6 -> 0
D19: T | K19: =SUM(E19:J19) -> 0 | L19: =K19/6 -> 0
B21: HABILIDADE EM TREINAMENTO | C21: REFORÇADOR | D21: TENTATIVAS | E21: 1 | F21: 2 | G21: 3 | H21: 4 | I21: 5 | J21: 6 | K21: TOTAL | L21: % | M21: OBSERVAÇÕES
B22: Permanecer no jogo até o final | D22: I | K22: =SUM(E22:J22) -> 0 | L22: =K22/6 -> 0
D23: P | K23: =SUM(E23:J23) -> 0 | L23: =K23/6 -> 0
D24: T | K24: =SUM(E24:J24) -> 0 | L24: =K24/6 -> 0
B26: HABILIDADE EM TREINAMENTO | C26: REFORÇADOR | D26: TENTATIVAS | E26: 1 | F26: 2 | G26: 3 | H26: 4 | I26: 5 | J26: 6 | K26: TOTAL | L26: % | M26: OBSERVAÇÕES
B27: Aceitar o fim da brincadeira sem chorar | D27: I | K27: =SUM(E27:J27) -> 0 | L27: =K27/6 -> 0
D28: P | K28: =SUM(E28:J28) -> 0 | L28: =K28/6 -> 0
D29: T | K29: =SUM(E29:J29) -> 0 | L29: =K29/6 -> 0

Sheet DIA 26
C2: PROTOCOLO DE APLICAÇÃO E REGISTRO | D2: TREINO
E3: DATA
D4: LEGENDA | F4: I = Resposta sem ajuda (independente) P = Resposta com ajuda parcial T = Resposta com ajuda total
B6: HABILIDADE EM TREINAMENTO | C6: REFORÇADOR | D6: TENTATIVAS | E6: 1 | F6: 2 | G6: 3 | H6: 4 | I6: 5 | J6: 6 | K6: TOTAL | L6: % | M6: OBSERVAÇÕES
B7: Seguir as regras do jogo | D7: I | K7: =SUM(E7:J7) -> 0 | L7: =K7/6 -> 0
D8: P | K8: =SUM(E8:J8) -> 0 | L8: =K8/6 -> 0
D9: T | K9: =SUM(E9:J9) -> 0 | L9: =K9/6 -> 0
B11: HABILIDADE EM TREINAMENTO | C11: REFORÇADOR | D11: TENTATIVAS | E11: 1 | F11: 2 | G11: 3 | H11: 4 | I11: 5 | J11: 6 | K11: TOTAL | L11: % | M11: OBSERVAÇÕES
B12: Esperar a sua vez | D12: I | K12: =SUM(E12:J12) -> 0 | L12: =K12/6 -> 0
D13: P | K13: =SUM(E13:J13) -> 0 | L13: =K13/6 -> 0
D14: T | K14: =SUM(E14:J14) -> 0 | L14: =K14/6 -> 0
B16: HABILIDADE EM TREINAMENTO | C16: REFORÇADOR | D16: TENTATIVAS | E16: 1 | F16: 2 | G16: 3 | H16: 4 | I16: 5 | J16: 6 | K16: TOTAL | L16: % | M16: OBSERVAÇÕES
B17: Lidar com frustração de perder | D17: I | K17: =SUM(E17:J17) -> 0 | L17: =K17/6 -> 0
D18: P | K18: =SUM(E18:J18) -> 0 | L18: =K18/6 -> 0
D19: T | K19: =SUM(E19:J19) -> 0 | L19: =K19/6 -> 0
B21: HABILIDADE EM TREINAMENTO | C21: REFORÇADOR | D21: TENTATIVAS | E21: 1 | F21: 2 | G21: 3 | H21: 4 | I21: 5 | J21: 6 | K21: TOTAL | L21: % | M21: OBSERVAÇÕES
B22: Permanecer no jogo até o final | D22: I | K22: =SUM(E22:J22) -> 0 | L22: =K22/6 -> 0
D23: P | K23: =SUM(E23:J23) -> 0 | L23: =K23/6 -> 0
D24: T | K24: =SUM(E24:J24) -> 0 | L24: =K24/6 -> 0
B26: HABILIDADE EM TREINAMENTO | C26: REFORÇADOR | D26: TENTATIVAS | E26: 1 | F26: 2 | G26: 3 | H26: 4 | I26: 5 | J26: 6 | K26: TOTAL | L26: % | M26: OBSERVAÇÕES
B27: Aceitar o fim da brincadeira sem chorar | D27: I | K27: =SUM(E27:J27) -> 0 | L27: =K27/6 -> 0
D28: P | K28: =SUM(E28:J28) -> 0 | L28: =K28/6 -> 0
D29: T | K29: =SUM(E29:J29) -> 0 | L29: =K29/6 -> 0

Sheet DIA 27
C2: PROTOCOLO DE APLICAÇÃO E REGISTRO | D2: TREINO
E3: DATA
D4: LEGENDA | F4: I = Resposta sem ajuda (independente) P = Resposta com ajuda parcial T = Resposta com ajuda total
B6: HABILIDADE EM TREINAMENTO | C6: REFORÇADOR | D6: TENTATIVAS | E6: 1 | F6: 2 | G6: 3 | H6: 4 | I6: 5 | J6: 6 | K6: TOTAL | L6: % | M6: OBSERVAÇÕES
B7: Seguir as regras do jogo | D7: I | K7: =SUM(E7:J7) -> 0 | L7: =K7/6 -> 0
D8: P | K8: =SUM(E8:J8) -> 0 | L8: =K8/6 -> 0
D9: T | K9: =SUM(E9:J9) -> 0 | L9: =K9/6 -> 0
B11: HABILIDADE EM TREINAMENTO | C11: REFORÇADOR | D11: TENTATIVAS | E11: 1 | F11: 2 | G11: 3 | H11: 4 | I11: 5 | J11: 6 | K11: TOTAL | L11: % | M11: OBSERVAÇÕES
B12: Esperar a sua vez | D12: I | K12: =SUM(E12:J12) -> 0 | L12: =K12/6 -> 0
D13: P | K13: =SUM(E13:J13) -> 0 | L13: =K13/6 -> 0
D14: T | K14: =SUM(E14:J14) -> 0 | L14: =K14/6 -> 0
B16: HABILIDADE EM TREINAMENTO | C16: REFORÇADOR | D16: TENTATIVAS | E16: 1 | F16: 2 | G16: 3 | H16: 4 | I16: 5 | J16: 6 | K16: TOTAL | L16: % | M16: OBSERVAÇÕES
B17: Lidar com frustração de perder | D17: I | K17: =SUM(E17:J17) -> 0 | L17: =K17/6 -> 0
D18: P | K18: =SUM(E18:J18) -> 0 | L18: =K18/6 -> 0
D19: T | K19: =SUM(E19:J19) -> 0 | L19: =K19/6 -> 0
B21: HABILIDADE EM TREINAMENTO | C21: REFORÇADOR | D21: TENTATIVAS | E21: 1 | F21: 2 | G21: 3 | H21: 4 | I21: 5 | J21: 6 | K21: TOTAL | L21: % | M21: OBSERVAÇÕES
B22: Permanecer no jogo até o final | D22: I | K22: =SUM(E22:J22) -> 0 | L22: =K22/6 -> 0
D23: P | K23: =SUM(E23:J23) -> 0 | L23: =K23/6 -> 0
D24: T | K24: =SUM(E24:J24) -> 0 | L24: =K24/6 -> 0
B26: HABILIDADE EM TREINAMENTO | C26: REFORÇADOR | D26: TENTATIVAS | E26: 1 | F26: 2 | G26: 3 | H26: 4 | I26: 5 | J26: 6 | K26: TOTAL | L26: % | M26: OBSERVAÇÕES
B27: Aceitar o fim da brincadeira sem chorar | D27: I | K27: =SUM(E27:J27) -> 0 | L27: =K27/6 -> 0
D28: P | K28: =SUM(E28:J28) -> 0 | L28: =K28/6 -> 0
D29: T | K29: =SUM(E29:J29) -> 0 | L29: =K29/6 -> 0

Sheet DIA 28
C2: PROTOCOLO DE APLICAÇÃO E REGISTRO | D2: TREINO
E3: DATA
D4: LEGENDA | F4: I = Resposta sem ajuda (independente) P = Resposta com ajuda parcial T = Resposta com ajuda total
B6: HABILIDADE EM TREINAMENTO | C6: REFORÇADOR | D6: TENTATIVAS | E6: 1 | F6: 2 | G6: 3 | H6: 4 | I6: 5 | J6: 6 | K6: TOTAL | L6: % | M6: OBSERVAÇÕES
B7: Seguir as regras do jogo | D7: I | K7: =SUM(E7:J7) -> 0 | L7: =K7/6 -> 0
D8: P | K8: =SUM(E8:J8) -> 0 | L8: =K8/6 -> 0
D9: T | K9: =SUM(E9:J9) -> 0 | L9: =K9/6 -> 0
B11: HABILIDADE EM TREINAMENTO | C11: REFORÇADOR | D11: TENTATIVAS | E11: 1 | F11: 2 | G11: 3 | H11: 4 | I11: 5 | J11: 6 | K11: TOTAL | L11: % | M11: OBSERVAÇÕES
B12: Esperar a sua vez | D12: I | K12: =SUM(E12:J12) -> 0 | L12: =K12/6 -> 0
D13: P | K13: =SUM(E13:J13) -> 0 | L13: =K13/6 -> 0
D14: T | K14: =SUM(E14:J14) -> 0 | L14: =K14/6 -> 0
B16: HABILIDADE EM TREINAMENTO | C16: REFORÇADOR | D16: TENTATIVAS | E16: 1 | F16: 2 | G16: 3 | H16: 4 | I16: 5 | J16: 6 | K16: TOTAL | L16: % | M16: OBSERVAÇÕES
B17: Lidar com frustração de perder | D17: I | K17: =SUM(E17:J17) -> 0 | L17: =K17/6 -> 0
D18: P | K18: =SUM(E18:J18) -> 0 | L18: =K18/6 -> 0
D19: T | K19: =SUM(E19:J19) -> 0 | L19: =K19/6 -> 0
B21: HABILIDADE EM TREINAMENTO | C21: REFORÇADOR | D21: TENTATIVAS | E21: 1 | F21: 2 | G21: 3 | H21: 4 | I21: 5 | J21: 6 | K21: TOTAL | L21: % | M21: OBSERVAÇÕES
B22: Permanecer no jogo até o final | D22: I | K22: =SUM(E22:J22) -> 0 | L22: =K22/6 -> 0
D23: P | K23: =SUM(E23:J23) -> 0 | L23: =K23/6 -> 0
D24: T | K24: =SUM(E24:J24) -> 0 | L24: =K24/6 -> 0
B26: HABILIDADE EM TREINAMENTO | C26: REFORÇADOR | D26: TENTATIVAS | E26: 1 | F26: 2 | G26: 3 | H26: 4 | I26: 5 | J26: 6 | K26: TOTAL | L26: % | M26: OBSERVAÇÕES
B27: Aceitar o fim da brincadeira sem chorar | D27: I | K27: =SUM(E27:J27) -> 0 | L27: =K27/6 -> 0
D28: P | K28: =SUM(E28:J28) -> 0 | L28: =K28/6 -> 0
D29: T | K29: =SUM(E29:J29) -> 0 | L29: =K29/6 -> 0

Sheet DIA 29
C2: PROTOCOLO DE APLICAÇÃO E REGISTRO | D2: TREINO
E3: DATA
D4: LEGENDA | F4: I = Resposta sem ajuda (independente) P = Resposta com ajuda parcial T = Resposta com ajuda total
B6: HABILIDADE EM TREINAMENTO | C6: REFORÇADOR | D6: TENTATIVAS | E6: 1 | F6: 2 | G6: 3 | H6: 4 | I6: 5 | J6: 6 | K6: TOTAL | L6: % | M6: OBSERVAÇÕES
B7: Seguir as regras do jogo | D7: I | K7: =SUM(E7:J7) -> 0 | L7: =K7/6 -> 0
D8: P | K8: =SUM(E8:J8) -> 0 | L8: =K8/6 -> 0
D9: T | K9: =SUM(E9:J9) -> 0 | L9: =K9/6 -> 0
B11: HABILIDADE EM TREINAMENTO | C11: REFORÇADOR | D11: TENTATIVAS | E11: 1 | F11: 2 | G11: 3 | H11: 4 | I11: 5 | J11: 6 | K11: TOTAL | L11: % | M11: OBSERVAÇÕES
B12: Esperar a sua vez | D12: I | K12: =SUM(E12:J12) -> 0 | L12: =K12/6 -> 0
D13: P | K13: =SUM(E13:J13) -> 0 | L13: =K13/6 -> 0
D14: T | K14: =SUM(E14:J14) -> 0 | L14: =K14/6 -> 0
B16: HABILIDADE EM TREINAMENTO | C16: REFORÇADOR | D16: TENTATIVAS | E16: 1 | F16: 2 | G16: 3 | H16: 4 | I16: 5 | J16: 6 | K16: TOTAL | L16: % | M16: OBSERVAÇÕES
B17: Lidar com frustração de perder | D17: I | K17: =SUM(E17:J17) -> 0 | L17: =K17/6 -> 0
D18: P | K18: =SUM(E18:J18) -> 0 | L18: =K18/6 -> 0
D19: T | K19: =SUM(E19:J19) -> 0 | L19: =K19/6 -> 0
