Workbook

Sheet Folha de Rosto 
C6: Folha de rosto para impressão com as informações do Aprendiz

Sheet Anamnese
C3: Informações Importantes da Anamnese -Entrevista com os Pais

Sheet CP
C4: Histórico do comportamento problema

Sheet INSTRUÇÕES
B2: Seja bem-vindo(a) à sua Folha de Registro Eletrônica 2025!
B4: Passo a Passo para o preenchimento:
B5: 1. Insira o título do Programa
B6: 2. Você pode inserir até 3 Sd (Estímulos Discriminativos) por programa
B7: 3. Podem ser registrados até 10 programas por dia para a criança
B8: 4. O tipo de Ajuda já consta nas opções da célula/campo de Ajuda. Basta selecionar. Não precisa digitar textos nesse campo.
B9: 5. Acertos: insira o número total de acertos que a criança obteve
B10: 6. Tentativas: insira o número total de tentativas realizadas pelo aplicador.
B11: Obs: DIV/0 não é erro. Representa apenas que não foram inseridos acertos e tentativas naquele dia. Não altera o gráfico final.
B12: Ao final do preenchimento, os gráficos de evolução da criança sairão automaticamente.
B14: Sucesso para você em sua jornada profissional!
B15: Sucesso às nossas crianças!

Sheet mês 1
B1: TODOS OS DIREITOS RESERVADOS À PLANILHA E CIA - Nº DE SÉRIE DO USUÁRIO: 0024001813| PROIBIDO O RATEIO, A COMERCIALIZAÇÃO E A REPRODUÇÃO DESSE MATERIAL PROIBIDO O USO DESSE MATERIAL POR MAIS DE UM USUÁRIO, SALVO SE A COMPRA TIVER OCORRIDO ATRAVÉS DO CNPJ DA CLÍNICA. MULTIPROFISSIONAL.
B3: REGISTRO DE PROGRAMAS - 2025
B5: Criança: | C5: PROGRAMA 1 | D5: Imitação | F5: PROGRAMA 2 | G5: Brincar Social | I5: PROGRAMA 3 | L5: PROGRAMA 4 | O5: PROGRAMA 5 | R5: PROGRAMA 6 | U5: PROGRAMA 7 | X5: PROGRAMA 8 | AA5: PROGRAMA 9 | AD5: PROGRAMA 10
B6: Lucas ABC
B7: Aplicador:
B8: Natasha XYZ
B22: * Preencha na tabela todos os dados coletados nos treinos com a criança. Não preencha a linha em roxo de %acertos, que possui fórmula.
B23: Data | C23: 45717 | D23: 45718 | E23: 45719 | F23: 45720 | G23: 45721 | H23: 45722 | I23: 45723 | J23: 45724 | K23: 45725 | L23: 45726 | M23: 45727 | N23: 45728 | O23: 45729 | P23: 45730 | Q23: 45731 | R23: 45732 | S23: 45733 | T23: 45734 | U23: 45735 | V23: 45736 | W23: 45737 | X23: 45738 | Y23: 45739 | Z23: 45740 | AA23: 45741 | AB23: 45742 | AC23: 45743 | AD23: 45744 | AE23: 45745 | AF23: 45746 | AG23: 45747 | AH23: % TOTAL ACERTOS
B24: PROGRAMA 1 | C24: GDFFB | D24: Imitação
B25: Estimulos Discriminativos (Sd) | C25: Carro | D25: Bola
C26: "(nome) faz igual" | D26: "(nome) faz igual"
B28: AJUDA | C28: Verbal | D28: Gestual | E28: Visual | F28: Física Parcial | G28: Faz Independente | H28: Gestual | I28: Gestual | J28: Gestual | K28: Gestual | L28: Gestual | M28: Gestual | N28: Gestual | O28: Gestual | P28: Gestual | Q28: Gestual | R28: Gestual | S28: Gestual | T28: Gestual | U28: Gestual | V28: Gestual | W28: Gestual | X28: Gestual | Y28: Gestual | Z28: Gestual | AA28: Gestual | AB28: Gestual | AC28: Gestual | AD28: Gestual | AE28: Gestual | AF28: Gestual | AG28: Gestual
B29: ACERTOS | C29: 20 | D29: 20 | E29: 8 | F29: 8 | G29: 8 | H29: 8 | I29: 8 | J29: 8 | K29: 8 | L29: 8 | M29: 8 | N29: 8 | O29: 8 | P29: 8 | Q29: 8 | R29: 8 | S29: 8 | T29: 8 | U29: 8 | V29: 8 | W29: 8 | X29: 8 | Y29: 8 | Z29: 8 | AA29: 8 | AB29: 8 | AC29: 8 | AD29: 8 | AE29: 8 | AF29: 8 | AG29: 8 | AH29: =SUM(C29:AG29) -> 272
B30: TENTATIVAS | C30: 30 | D30: 30 | E30: 10 | F30: 10 | G30: 10 | H30: 10 | I30: 10 | J30: 10 | K30: 10 | L30: 10 | M30: 10 | N30: 10 | O30: 10 | P30: 10 | Q30: 10 | R30: 10 | S30: 10 | T30: 10 | U30: 10 | V30: 10 | W30: 10 | X30: 10 | Y30: 10 | Z30: 10 | AA30: 10 | AB30: 10 | AC30: 10 | AD30: 10 | AE30: 10 | AF30: 10 | AG30: 10 | AH30: =SUM(C30:AG30) -> 350
B31: % ACERTOS | C31: =C29/C30 -> 0.66666667 | D31: =D29/D30 -> 0.66666667 | E31: =E29/E30 -> 0.8 | F31: =F29/F30 -> 0.8 | G31: =G29/G30 -> 0.8 | H31: =H29/H30 -> 0.8 | I31: =I29/I30 -> 0.8 | J31: =J29/J30 -> 0.8 | ... AH31: =AH29/AH30 -> 0.77714286
B33: PROGRAMA 2 | C33: Brincar Social | D33: Brincar Social | E33: Brincar Social | F33: Brincar Social | G33: Brincar Social | H33: Brincar Social | AH33: % TOTAL ACERTOS
B34: Estimulos Discriminativos (Sd) | C34: Bola | D34: Bola | E34: Bola | F34: Bola | G34: Bola | H34: Bola
C35: "(nome) joga para mim" | D35: "(nome) joga para mim" | E35: "(nome) joga para mim" | F35: "(nome) joga para mim" | G35: "(nome) joga para mim" | H35: "(nome) joga para mim"
B37: AJUDA | C37: Gestual | D37: Gestual | E37: Gestual | F37: Gestual | G37: Gestual | H37: Gestual | I37: Visual | J37: Gestual | K37: Gestual | L37: Gestual | M37: Gestual | N37: Gestual | O37: Gestual | P37: Física Total | Q37: Visual | R37: Não Faz | S37: Gestual | T37: Gestual | U37: Gestual | V37: Gestual | W37: Gestual | X37: Gestual | Y37: Gestual | Z37: Gestual | AA37: Gestual | AB37: Gestual | AC37: Gestual | AD37: Gestual | AE37: Gestual | AF37: Gestual | AG37: Gestual
B38: ACERTOS | C38: 20 | D38: 20 | E38: 20 | F38: 20 | G38: 20 | H38: 20 | I38: 20 | J38: 20 | K38: 20 | L38: 20 | M38: 20 | N38: 20 | O38: 20 | P38: 9 | Q38: 20 | R38: 20 | S38: 20 | T38: 20 | U38: 20 | V38: 20 | W38: 20 | X38: 20 | Y38: 20 | Z38: 20 | AA38: 20 | AB38: 20 | AC38: 20 | AD38: 20 | AE38: 20 | AF38: 20 | AG38: 20 | AH38: =SUM(C38:AG38) -> 609
B39: TENTATIVAS | C39: 30 | D39: 30 | E39: 30 | F39: 30 | G39: 30 | H39: 30 | I39: 30 | J39: 30 | K39: 30 | L39: 30 | M39: 30 | N39: 30 | O39: 30 | P39: 10 | Q39: 30 | R39: 30 | S39: 30 | T39: 30 | U39: 30 | V39: 30 | W39: 30 | X39: 30 | Y39: 30 | Z39: 30 | AA39: 30 | AB39: 30 | AC39: 30 | AD39: 30 | AE39: 30 | AF39: 30 | AG39: 30 | AH39: =SUM(C39:AG39) -> 910
B40: % ACERTOS | C40: =C38/C39 -> 0.66666667 | D40: =D38/D39 -> 0.66666667 | E40: =E38/E39 -> 0.66666667 | F40: =F38/F39 -> 0.66666667 | G40: =G38/G39 -> 0.66666667 | H40: =H38/H39 -> 0.66666667 | I40: =I38/I39 -> 0.66666667 | J40: =J38/J39 -> 0.66666667 | ... AH40: =AH38/AH39 -> 0.66923077
B42: PROGRAMA 3 | C42: Brincar Social | D42: Brincar Social | E42: Brincar Social | F42: Brincar Social | G42: Brincar Social | H42: Brincar Social | AH42: % TOTAL ACERTOS
B43: Estimulos Discriminativos (Sd) | C43: Bola | D43: Bola | E43: Bola | F43: Bola | G43: Bola | H43: Bola
C44: "(nome) joga para mim" | D44: "(nome) joga para mim" | E44: "(nome) joga para mim" | F44: "(nome) joga para mim" | G44: "(nome) joga para mim" | H44: "(nome) joga para mim"
B46: AJUDA | C46: Gestual | D46: Gestual | E46: Gestual | F46: Gestual | G46: Gestual | H46: Gestual | I46: Visual | J46: Gestual | K46: Gestual | L46: Gestual | M46: Gestual | N46: Gestual | O46: Gestual | P46: Física Total | Q46: Visual | R46: Não Faz | S46: Gestual | T46: Gestual | U46: Gestual | V46: Gestual | W46: Gestual | X46: Gestual | Y46: Gestual | Z46: Gestual | AA46: Gestual | AB46: Gestual | AC46: Gestual | AD46: Gestual | AE46: Gestual | AF46: Gestual | AG46: Gestual
B47: ACERTOS | C47: 20 | D47: 20 | E47: 20 | F47: 20 | G47: 20 | H47: 20 | I47: 20 | J47: 20 | K47: 20 | L47: 20 | M47: 20 | N47: 20 | O47: 20 | P47: 9 | Q47: 20 | R47: 20 | S47: 20 | T47: 20 | U47: 20 | V47: 20 | W47: 20 | X47: 20 | Y47: 20 | Z47: 20 | AA47: 20 | AB47: 20 | AC47: 20 | AD47: 20 | AE47: 20 | AF47: 20 | AG47: 20 | AH47: =SUM(C47:AG47) -> 609
B48: TENTATIVAS | C48: 30 | D48: 30 | E48: 30 | F48: 30 | G48: 30 | H48: 30 | I48: 30 | J48: 30 | K48: 30 | L48: 30 | M48: 30 | N48: 30 | O48: 30 | P48: 10 | Q48: 30 | R48: 30 | S48: 30 | T48: 30 | U48: 30 | V48: 30 | W48: 30 | X48: 30 | Y48: 30 | Z48: 30 | AA48: 30 | AB48: 30 | AC48: 30 | AD48: 30 | AE48: 30 | AF48: 30 | AG48: 30 | AH48: =SUM(C48:AG48) -> 910
B49: % ACERTOS | C49: =C47/C48 -> 0.66666667 | D49: =D47/D48 -> 0.66666667 | E49: =E47/E48 -> 0.66666667 | F49: =F47/F48 -> 0.66666667 | G49: =G47/G48 -> 0.66666667 | H49: =H47/H48 -> 0.66666667 | I49: =I47/I48 -> 0.66666667 | J49: =J47/J48 -> 0.66666667 | ... AH49: =AH47/AH48 -> 0.66923077
B51: PROGRAMA 4 | C51: Brincar Social | D51: Brincar Social | E51: Brincar Social | F51: Brincar Social | G51: Brincar Social | H51: Brincar Social | AH51: % TOTAL ACERTOS
B52: Estimulos Discriminativos (Sd) | C52: Bola | D52: Bola | E52: Bola | F52: Bola | G52: Bola | H52: Bola
C53: "(nome) joga para mim" | D53: "(nome) joga para mim" | E53: "(nome) joga para mim" | F53: "(nome) joga para mim" | G53: "(nome) joga para mim" | H53: "(nome) joga para mim"
B55: AJUDA | C55: Gestual | D55: Gestual | E55: Gestual | F55: Gestual | G55: Gestual | H55: Gestual | I55: Visual | J55: Gestual | K55: Gestual | L55: Gestual | M55: Gestual | N55: Gestual | O55: Gestual | P55: Física Total | Q55: Visual | R55: Não Faz | S55: Gestual | T55: Gestual | U55: Gestual | V55: Gestual | W55: Gestual | X55: Gestual | Y55: Gestual | Z55: Gestual | AA55: Gestual | AB55: Gestual | AC55: Gestual | AD55: Gestual | AE55: Gestual | AF55: Gestual | AG55: Gestual
B56: ACERTOS | C56: 20 | D56: 20 | E56: 20 | F56: 20 | G56: 20 | H56: 20 | I56: 20 | J56: 20 | K56: 20 | L56: 20 | M56: 20 | N56: 20 | O56: 20 | P56: 9 | Q56: 20 | R56: 20 | S56: 20 | T56: 20 | U56: 20 | V56: 20 | W56: 20 | X56: 20 | Y56: 20 | Z56: 20 | AA56: 20 | AB56: 20 | AC56: 20 | AD56: 20 | AE56: 20 | AF56: 20 | AG56: 20 | AH56: =SUM(C56:AG56) -> 609
B57: TENTATIVAS | C57: 30 | D57: 30 | E57: 30 | F57: 30 | G57: 30 | H57: 30 | I57: 30 | J57: 30 | K57: 30 | L57: 30 | M57: 30 | N57: 30 | O57: 30 | P57: 10 | Q57: 30 | R57: 30 | S57: 30 | T57: 30 | U57: 30 | V57: 30 | W57: 30 | X57: 30 | Y57: 30 | Z57: 30 | AA57: 30 | AB57: 30 | AC57: 30 | AD57: 30 | AE57: 30 | AF57: 30 | AG57: 30 | AH57: =SUM(C57:AG57) -> 910
B58: % ACERTOS | C58: =C56/C57 -> 0.66666667 | D58: =D56/D57 -> 0.66666667 | E58: =E56/E57 -> 0.66666667 | F58: =F56/F57 -> 0.66666667 | G58: =G56/G57 -> 0.66666667 | H58: =H56/H57 -> 0.66666667 | I58: =I56/I57 -> 0.66666667 | J58: =J56/J57 -> 0.66666667 | ... AH58: =AH56/AH57 -> 0.66923077
B60: PROGRAMA 5 | C60: Brincar Social | D60: Brincar Social | E60: Brincar Social | F60: Brincar Social | G60: Brincar Social | H60: Brincar Social | AH60: % TOTAL ACERTOS
B61: Estimulos Discriminativos (Sd) | C61: Bola | D61: Bola | E61: Bola | F61: Bola | G61: Bola | H61: Bola
C62: "(nome) joga para mim" | D62: "(nome) joga para mim" | E62: "(nome) joga para mim" | F62: "(nome) joga para mim" | G62: "(nome) joga para mim" | H62: "(nome) joga para mim"
B64: AJUDA | C64: Gestual | D64: Gestual | E64: Gestual | F64: Gestual | G64: Gestual | H64: Gestual | I64: Visual | J64: Gestual | K64: Gestual | L64: Gestual | M64: Gestual | N64: Gestual | O64: Gestual | P64: Física Total | Q64: Visual | R64: Não Faz | S64: Gestual | T64: Gestual | U64: Gestual | V64: Gestual | W64: Gestual | X64: Gestual | Y64: Gestual | Z64: Gestual | AA64: Gestual | AB64: Gestual | AC64: Gestual | AD64: Gestual | AE64: Gestual | AF64: Gestual | AG64: Gestual
...

Sheet mês 2
B1: TODOS OS DIREITOS RESERVADOS À PLANILHA E CIA - Nº DE SÉRIE DO USUÁRIO: 0024001813| PROIBIDO O RATEIO, A COMERCIALIZAÇÃO E A REPRODUÇÃO DESSE MATERIAL PROIBIDO O USO DESSE MATERIAL POR MAIS DE UM USUÁRIO, SALVO SE A COMPRA TIVER OCORRIDO ATRAVÉS DO CNPJ DA CLÍNICA. MULTIPROFISSIONAL.
B3: REGISTRO DE PROGRAMAS - 2025
B5: Criança: | C5: PROGRAMA 1 | D5: Imitação | F5: PROGRAMA 2 | G5: Brincar Social | I5: PROGRAMA 3 | L5: PROGRAMA 4 | O5: PROGRAMA 5 | R5: PROGRAMA 6 | U5: PROGRAMA 7 | X5: PROGRAMA 8 | AA5: PROGRAMA 9 | AD5: PROGRAMA 10
B6: Lucas ABC
B7: Aplicador:
B8: Natasha XYZ
B22: * Preencha na tabela todos os dados coletados nos treinos com a criança. Não preencha a linha em roxo de %acertos, que possui fórmula.
B23: Data | C23: 45748 | D23: 45749 | E23: 45750 | F23: 45751 | G23: 45752 | H23: 45753 | I23: 45754 | J23: 45755 | K23: 45756 | L23: 45757 | M23: 45758 | N23: 45759 | O23: 45760 | P23: 45761 | Q23: 45762 | R23: 45763 | S23: 45764 | T23: 45765 | U23: 45766 | V23: 45767 | W23: 45768 | X23: 45769 | Y23: 45770 | Z23: 45771 | AA23: 45772 | AB23: 45773 | AC23: 45774 | AD23: 45775 | AE23: 45776 | AF23: 45777 | AG23: % TOTAL ACERTOS
B24: PROGRAMA 1 | C24: GDFFB | D24: Imitação
B25: Sd | C25: Carro | D25: Bola
C26: "(nome) faz igual" | D26: "(nome) faz igual"
B28: AJUDA | C28: Verbal | D28: Gestual | E28: Visual | F28: Física Parcial | G28: Faz Independente | H28: Gestual | I28: Gestual | J28: Gestual | K28: Gestual | L28: Gestual | M28: Gestual | N28: Gestual | O28: Gestual | P28: Gestual | Q28: Gestual | R28: Gestual | S28: Gestual | T28: Gestual | U28: Gestual | V28: Gestual | W28: Gestual | X28: Gestual | Y28: Gestual | Z28: Gestual | AA28: Gestual | AB28: Gestual | AC28: Gestual | AD28: Gestual | AE28: Gestual | AF28: Gestual
B29: ACERTOS | C29: 20 | D29: 20 | E29: 8 | F29: 8 | G29: 8 | H29: 8 | I29: 8 | J29: 8 | K29: 8 | L29: 8 | M29: 8 | N29: 8 | O29: 8 | P29: 8 | Q29: 8 | R29: 8 | S29: 8 | T29: 8 | U29: 8 | V29: 8 | W29: 8 | X29: 8 | Y29: 8 | Z29: 8 | AA29: 8 | AB29: 8 | AC29: 8 | AD29: 8 | AE29: 8 | AF29: 8 | AG29: =SUM(C29:AF29) -> 264
B30: TENTATIVAS | C30: 30 | D30: 30 | E30: 10 | F30: 10 | G30: 10 | H30: 10 | I30: 10 | J30: 10 | K30: 10 | L30: 10 | M30: 10 | N30: 10 | O30: 10 | P30: 10 | Q30: 10 | R30: 10 | S30: 10 | T30: 10 | U30: 10 | V30: 10 | W30: 10 | X30: 10 | Y30: 10 | Z30: 10 | AA30: 10 | AB30: 10 | AC30: 10 | AD30: 10 | AE30: 10 | AF30: 10 | AG30: =SUM(C30:AF30) -> 340
B31: % ACERTOS | C31: =C29/C30 -> 0.66666667 | D31: =D29/D30 -> 0.66666667 | E31: =E29/E30 -> 0.8 | F31: =F29/F30 -> 0.8 | G31: =G29/G30 -> 0.8 | H31: =H29/H30 -> 0.8 | I31: =I29/I30 -> 0.8 | J31: =J29/J30 -> 0.8 | ... AG31: =AG29/AG30 -> 0.77647059
B33: PROGRAMA 2 | C33: Brincar Social | D33: Brincar Social | E33: Brincar Social | F33: Brincar Social | G33: Brincar Social | H33: Brincar Social | AG33: % TOTAL ACERTOS
B34: Sd | C34: Bola | D34: Bola | E34: Bola | F34: Bola | G34: Bola | H34: Bola
C35: "(nome) joga para mim" | D35: "(nome) joga para mim" | E35: "(nome) joga para mim" | F35: "(nome) joga para mim" | G35: "(nome) joga para mim" | H35: "(nome) joga para mim"
B37: AJUDA | C37: Gestual | D37: Gestual | E37: Gestual | F37: Gestual | G37: Gestual | H37: Gestual | I37: Visual | J37: Gestual | K37: Gestual | L37: Gestual | M37: Gestual | N37: Gestual | O37: Gestual | P37: Física Total | Q37: Visual | R37: Não Faz | S37: Gestual | T37: Gestual | U37: Gestual | V37: Gestual | W37: Gestual | X37: Gestual | Y37: Gestual | Z37: Gestual | AA37: Gestual | AB37: Gestual | AC37: Gestual | AD37: Gestual | AE37: Gestual | AF37: Gestual
B38: ACERTOS | C38: 20 | D38: 20 | E38: 20 | F38: 20 | G38: 20 | H38: 20 | I38: 20 | J38: 20 | K38: 20 | L38: 20 | M38: 20 | N38: 20 | O38: 20 | P38: 9 | Q38: 20 | R38: 20 | S38: 20 | T38: 20 | U38: 20 | V38: 20 | W38: 20 | X38: 20 | Y38: 20 | Z38: 20 | AA38: 20 | AB38: 20 | AC38: 20 | AD38: 20 | AE38: 20 | AF38: 20 | AG38: =SUM(C38:AF38) -> 589
B39: TENTATIVAS | C39: 30 | D39: 30 | E39: 30 | F39: 30 | G39: 30 | H39: 30 | I39: 30 | J39: 30 | K39: 30 | L39: 30 | M39: 30 | N39: 30 | O39: 30 | P39: 10 | Q39: 30 | R39: 30 | S39: 30 | T39: 30 | U39: 30 | V39: 30 | W39: 30 | X39: 30 | Y39: 30 | Z39: 30 | AA39: 30 | AB39: 30 | AC39: 30 | AD39: 30 | AE39: 30 | AF39: 30 | AG39: =SUM(C39:AF39) -> 880
B40: % ACERTOS | C40: =C38/C39 -> 0.66666667 | D40: =D38/D39 -> 0.66666667 | E40: =E38/E39 -> 0.66666667 | F40: =F38/F39 -> 0.66666667 | G40: =G38/G39 -> 0.66666667 | H40: =H38/H39 -> 0.66666667 | I40: =I38/I39 -> 0.66666667 | J40: =J38/J39 -> 0.66666667 | ... AG40: =AG38/AG39 -> 0.66931818
B42: PROGRAMA 3 | C42: Brincar Social | D42: Brincar Social | E42: Brincar Social | F42: Brincar Social | G42: Brincar Social | H42: Brincar Social | AG42: % TOTAL ACERTOS
B43: Sd | C43: Bola | D43: Bola | E43: Bola | F43: Bola | G43: Bola | H43: Bola
C44: "(nome) joga para mim" | D44: "(nome) joga para mim" | E44: "(nome) joga para mim" | F44: "(nome) joga para mim" | G44: "(nome) joga para mim" | H44: "(nome) joga para mim"
B46: AJUDA | C46: Gestual | D46: Gestual | E46: Gestual | F46: Gestual | G46: Gestual | H46: Gestual | I46: Visual | J46: Gestual | K46: Gestual | L46: Gestual | M46: Gestual | N46: Gestual | O46: Gestual | P46: Física Total | Q46: Visual | R46: Não Faz | S46: Gestual | T46: Gestual | U46: Gestual | V46: Gestual | W46: Gestual | X46: Gestual | Y46: Gestual | Z46: Gestual | AA46: Gestual | AB46: Gestual | AC46: Gestual | AD46: Gestual | AE46: Gestual | AF46: Gestual
B47: ACERTOS | C47: 20 | D47: 20 | E47: 20 | F47: 20 | G47: 20 | H47: 20 | I47: 20 | J47: 20 | K47: 20 | L47: 20 | M47: 20 | N47: 20 | O47: 20 | P47: 9 | Q47: 20 | R47: 20 | S47: 20 | T47: 20 | U47: 20 | V47: 20 | W47: 20 | X47: 20 | Y47: 20 | Z47: 20 | AA47: 20 | AB47: 20 | AC47: 20 | AD47: 20 | AE47: 20 | AF47: 20 | AG47: =SUM(C47:AF47) -> 589
B48: TENTATIVAS | C48: 30 | D48: 30 | E48: 30 | F48: 30 | G48: 30 | H48: 30 | I48: 30 | J48: 30 | K48: 30 | L48: 30 | M48: 30 | N48: 30 | O48: 30 | P48: 10 | Q48: 30 | R48: 30 | S48: 30 | T48: 30 | U48: 30 | V48: 30 | W48: 30 | X48: 30 | Y48: 30 | Z48: 30 | AA48: 30 | AB48: 30 | AC48: 30 | AD48: 30 | AE48: 30 | AF48: 30 | AG48: =SUM(C48:AF48) -> 880
B49: % ACERTOS | C49: =C47/C48 -> 0.66666667 | D49: =D47/D48 -> 0.66666667 | E49: =E47/E48 -> 0.66666667 | F49: =F47/F48 -> 0.66666667 | G49: =G47/G48 -> 0.66666667 | H49: =H47/H48 -> 0.66666667 | I49: =I47/I48 -> 0.66666667 | J49: =J47/J48 -> 0.66666667 | ... AG49: =AG47/AG48 -> 0.66931818
B51: PROGRAMA 4 | C51: Brincar Social | D51: Brincar Social | E51: Brincar Social | F51: Brincar Social | G51: Brincar Social | H51: Brincar Social | AG51: % TOTAL ACERTOS
B52: Sd | C52: Bola | D52: Bola | E52: Bola | F52: Bola | G52: Bola | H52: Bola
C53: "(nome) joga para mim" | D53: "(nome) joga para mim" | E53: "(nome) joga para mim" | F53: "(nome) joga para mim" | G53: "(nome) joga para mim" | H53: "(nome) joga para mim"
B55: AJUDA | C55: Gestual | D55: Gestual | E55: Gestual | F55: Gestual | G55: Gestual | H55: Gestual | I55: Visual | J55: Gestual | K55: Gestual | L55: Gestual | M55: Gestual | N55: Gestual | O55: Gestual | P55: Física Total | Q55: Visual | R55: Não Faz | S55: Gestual | T55: Gestual | U55: Gestual | V55: Gestual | W55: Gestual | X55: Gestual | Y55: Gestual | Z55: Gestual | AA55: Gestual | AB55: Gestual | AC55: Gestual | AD55: Gestual | AE55: Gestual | AF55: Gestual
B56: ACERTOS | C56: 20 | D56: 20 | E56: 20 | F56: 20 | G56: 20 | H56: 20 | I56: 20 | J56: 20 | K56: 20 | L56: 20 | M56: 20 | N56: 20 | O56: 20 | P56: 9 | Q56: 20 | R56: 20 | S56: 20 | T56: 20 | U56: 20 | V56: 20 | W56: 20 | X56: 20 | Y56: 20 | Z56: 20 | AA56: 20 | AB56: 20 | AC56: 20 | AD56: 20 | AE56: 20 | AF56: 20 | AG56: =SUM(C56:AF56) -> 589
B57: TENTATIVAS | C57: 30 | D57: 30 | E57: 30 | F57: 30 | G57: 30 | H57: 30 | I57: 30 | J57: 30 | K57: 30 | L57: 30 | M57: 30 | N57: 30 | O57: 30 | P57: 10 | Q57: 30 | R57: 30 | S57: 30 | T57: 30 | U57: 30 | V57: 30 | W57: 30 | X57: 30 | Y57: 30 | Z57: 30 | AA57: 30 | AB57: 30 | AC57: 30 | AD57: 30 | AE57: 30 | AF57: 30 | AG57: =SUM(C57:AF57) -> 880
B58: % ACERTOS | C58: =C56/C57 -> 0.66666667 | D58: =D56/D57 -> 0.66666667 | E58: =E56/E57 -> 0.66666667 | F58: =F56/F57 -> 0.66666667 | G58: =G56/G57 -> 0.66666667 | H58: =H56/H57 -> 0.66666667 | I58: =I56/I57 -> 0.66666667 | J58: =J56/J57 -> 0.66666667 | ... AG58: =AG56/AG57 -> 0.66931818
B60: PROGRAMA 5 | C60: Brincar Social | D60: Brincar Social | E60: Brincar Social | F60: Brincar Social | G60: Brincar Social | H60: Brincar Social | AG60: % TOTAL ACERTOS
B61: Sd | C61: Bola | D61: Bola | E61: Bola | F61: Bola | G61: Bola | H61: Bola
C62: "(nome) joga para mim" | D62: "(nome) joga para mim" | E62: "(nome) joga para mim" | F62: "(nome) joga para mim" | G62: "(nome) joga para mim" | H62: "(nome) joga para mim"
B64: AJUDA | C64: Gestual | D64: Gestual | E64: Gestual | F64: Gestual | G64: Gestual | H64: Gestual | I64: Visual | J64: Gestual | K64: Gestual | L64: Gestual | M64: Gestual | N64: Gestual | O64: Gestual | P64: Física Total | Q64: Visual | R64: Não Faz | S64: Gestual | T64: Gestual | U64: Gestual | V64: Gestual | W64: Gestual | X64: Gestual | Y64: Gestual | Z64: Gestual | AA64: Gestual | AB64: Gestual | AC64: Gestual | AD64: Gestual | AE64: Gestual | AF64: Gestual
...

Sheet mês 3
B1: TODOS OS DIREITOS RESERVADOS À PLANILHA E CIA - Nº DE SÉRIE DO USUÁRIO: 0024001813| PROIBIDO O RATEIO, A COMERCIALIZAÇÃO E A REPRODUÇÃO DESSE MATERIAL PROIBIDO O USO DESSE MATERIAL POR MAIS DE UM USUÁRIO, SALVO SE A COMPRA TIVER OCORRIDO ATRAVÉS DO CNPJ DA CLÍNICA. MULTIPROFISSIONAL.
B3: REGISTRO DE PROGRAMAS - 2025
B5: Criança: | C5: PROGRAMA 1 | D5: Imitação | F5: PROGRAMA 2 | G5: Brincar Social | I5: PROGRAMA 3 | L5: PROGRAMA 4 | O5: PROGRAMA 5 | R5: PROGRAMA 6 | U5: PROGRAMA 7 | X5: PROGRAMA 8 | AA5: PROGRAMA 9 | AD5: PROGRAMA 10
B6: Lucas ABC
B7: Aplicador:
B8: Natasha XYZ
B22: * Preencha na tabela todos os dados coletados nos treinos com a criança. Não preencha a linha em roxo de %acertos, que possui fórmula.
B23: Data | C23: 45778 | D23: 45779 | E23: 45780 | F23: 45781 | G23: 45782 | H23: 45783 | I23: 45784 | J23: 45785 | K23: 45786 | L23: 45787 | M23: 45788 | N23: 45789 | O23: 45790 | P23: 45791 | Q23: 45792 | R23: 45793 | S23: 45794 | T23: 45795 | U23: 45796 | V23: 45797 | W23: 45798 | X23: 45799 | Y23: 45800 | Z23: 45801 | AA23: 45802 | AB23: 45803 | AC23: 45804 | AD23: 45805 | AE23: 45806 | AF23: 45807 | AG23: 45808 | AH23: % TOTAL ACERTOS
B24: PROGRAMA 1 | C24: Imitação | D24: Imitação
B25: Sd | C25: Carro | D25: Bola
C26: "(nome) faz igual" | D26: "(nome) faz igual"
B28: AJUDA | C28: Gestual | D28: Gestual | E28: Visual | F28: Física Parcial | G28: Faz Independente | H28: Gestual | I28: Gestual | J28: Gestual | K28: Gestual | L28: Gestual | M28: Gestual | N28: Gestual | O28: Gestual | P28: Gestual | Q28: Gestual | R28: Gestual | S28: Gestual | T28: Gestual | U28: Gestual | V28: Gestual | W28: Gestual | X28: Gestual | Y28: Gestual | Z28: Gestual | AA28: Gestual | AB28: Gestual | AC28: Gestual | AD28: Gestual | AE28: Gestual | AF28: Gestual | AG28: Gestual
B29: ACERTOS | C29: 20 | D29: 20 | E29: 8 | F29: 8 | G29: 8 | H29: 8 | I29: 8 | J29: 8 | K29: 8 | L29: 8 | M29: 8 | N29: 8 | O29: 8 | P29: 8 | Q29: 8 | R29: 8 | S29: 8 | T29: 8 | U29: 8 | V29: 8 | W29: 8 | X29: 8 | Y29: 8 | Z29: 8 | AA29: 8 | AB29: 8 | AC29: 8 | AD29: 8 | AE29: 8 | AF29: 8 | AG29: 8 | AH29: =SUM(C29:AG29) -> 272
B30: TENTATIVAS | C30: 30 | D30: 30 | E30: 10 | F30: 10 | G30: 10 | H30: 10 | I30: 10 | J30: 10 | K30: 10 | L30: 10 | M30: 10 | N30: 10 | O30: 10 | P30: 10 | Q30: 10 | R30: 10 | S30: 10 | T30: 10 | U30: 10 | V30: 10 | W30: 10 | X30: 10 | Y30: 10 | Z30: 10 | AA30: 10 | AB30: 10 | AC30: 10 | AD30: 10 | AE30: 10 | AF30: 10 | AG30: 10 | AH30: =SUM(C30:AG30) -> 350
B31: % ACERTOS | C31: =C29/C30 -> 0.66666667 | D31: =D29/D30 -> 0.66666667 | E31: =E29/E30 -> 0.8 | F31: =F29/F30 -> 0.8 | G31: =G29/G30 -> 0.8 | H31: =H29/H30 -> 0.8 | I31: =I29/I30 -> 0.8 | J31: =J29/J30 -> 0.8 | ... AH31: =AH29/AH30 -> 0.77714286
B33: PROGRAMA 2 | C33: Brincar Social | D33: Brincar Social | E33: Brincar Social | F33: Brincar Social | G33: Brincar Social | H33: Brincar Social | AH33: % TOTAL ACERTOS
B34: Sd
B37: AJUDA | K37: Gestual | L37: Gestual | M37: Gestual | N37: Gestual | O37: Gestual | P37: Física Total | Q37: Visual | R37: Não Faz | S37: Gestual | T37: Gestual | U37: Gestual | V37: Gestual | W37: Gestual | X37: Gestual | Y37: Gestual | Z37: Gestual | AA37: Gestual | AB37: Gestual | AC37: Gestual | AD37: Gestual | AE37: Gestual | AF37: Gestual | AG37: Gestual
B38: ACERTOS | K38: 20 | L38: 20 | M38: 20 | N38: 20 | O38: 20 | P38: 9 | Q38: 20 | R38: 20 | S38: 20 | T38: 20 | U38: 20 | V38: 20 | W38: 20 | X38: 20 | Y38: 20 | Z38: 20 | AA38: 20 | AB38: 20 | AC38: 20 | AD38: 20 | AE38: 20 | AF38: 20 | AG38: 20 | AH38: =SUM(C38:AG38) -> 449
B39: TENTATIVAS | K39: 30 | L39: 30 | M39: 30 | N39: 30 | O39: 30 | P39: 10 | Q39: 30 | R39: 30 | S39: 30 | T39: 30 | U39: 30 | V39: 30 | W39: 30 | X39: 30 | Y39: 30 | Z39: 30 | AA39: 30 | AB39: 30 | AC39: 30 | AD39: 30 | AE39: 30 | AF39: 30 | AG39: 30 | AH39: =SUM(C39:AG39) -> 670
B40: % ACERTOS | C40: =C38/C39 -> #DIV/0! | D40: =D38/D39 -> #DIV/0! | E40: =E38/E39 -> #DIV/0! | F40: =F38/F39 -> #DIV/0! | G40: =G38/G39 -> #DIV/0! | H40: =H38/H39 -> #DIV/0! | I40: =I38/I39 -> #DIV/0! | J40: =J38/J39 -> #DIV/0! | ... AH40: =AH38/AH39 -> 0.67014925
B42: PROGRAMA 3 | C42: Brincar Social | D42: Brincar Social | E42: Brincar Social | F42: Brincar Social | G42: Brincar Social | H42: Brincar Social | AH42: % TOTAL ACERTOS
B43: Sd | C43: Bola | D43: Bola | E43: Bola | F43: Bola | G43: Bola | H43: Bola
C44: "(nome) joga para mim" | D44: "(nome) joga para mim" | E44: "(nome) joga para mim" | F44: "(nome) joga para mim" | G44: "(nome) joga para mim" | H44: "(nome) joga para mim"
B46: AJUDA | C46: Gestual | D46: Gestual | E46: Gestual | F46: Gestual | G46: Gestual | H46: Gestual | I46: Visual | J46: Gestual | K46: Gestual | L46: Gestual | M46: Gestual | N46: Gestual | O46: Gestual | P46: Física Total | Q46: Visual | R46: Não Faz | S46: Gestual | T46: Gestual | U46: Gestual | V46: Gestual | W46: Gestual | X46: Gestual | Y46: Gestual | Z46: Gestual | AA46: Gestual | AB46: Gestual | AC46: Gestual | AD46: Gestual | AE46: Gestual | AF46: Gestual | AG46: Gestual
B47: ACERTOS | C47: 20 | D47: 20 | E47: 20 | F47: 20 | G47: 20 | H47: 20 | I47: 20 | J47: 20 | K47: 20 | L47: 20 | M47: 20 | N47: 20 | O47: 20 | P47: 9 | Q47: 20 | R47: 20 | S47: 20 | T47: 20 | U47: 20 | V47: 20 | W47: 20 | X47: 20 | Y47: 20 | Z47: 20 | AA47: 20 | AB47: 20 | AC47: 20 | AD47: 20 | AE47: 20 | AF47: 20 | AG47: 20 | AH47: =SUM(C47:AG47) -> 609
B48: TENTATIVAS | C48: 30 | D48: 30 | E48: 30 | F48: 30 | G48: 30 | H48: 30 | I48: 30 | J48: 30 | K48: 30 | L48: 30 | M48: 30 | N48: 30 | O48: 30 | P48: 10 | Q48: 30 | R48: 30 | S48: 30 | T48: 30 | U48: 30 | V48: 30 | W48: 30 | X48: 30 | Y48: 30 | Z48: 30 | AA48: 30 | AB48: 30 | AC48: 30 | AD48: 30 | AE48: 30 | AF48: 30 | AG48: 30 | AH48: =SUM(C48:AG48) -> 910
B49: % ACERTOS | C49: =C47/C48 -> 0.66666667 | D49: =D47/D48 -> 0.66666667 | E49: =E47/E48 -> 0.66666667 | F49: =F47/F48 -> 0.66666667 | G49: =G47/G48 -> 0.66666667 | H49: =H47/H48 -> 0.66666667 | I49: =I47/I48 -> 0.66666667 | J49: =J47/J48 -> 0.66666667 | ... AH49: =AH47/AH48 -> 0.66923077
B51: PROGRAMA 4 | C51: Brincar Social | D51: Brincar Social | E51: Brincar Social | F51: Brincar Social | G51: Brincar Social | H51: Brincar Social | AH51: % TOTAL ACERTOS
B52: Sd | C52: Bola | D52: Bola | E52: Bola | F52: Bola | G52: Bola | H52: Bola
C53: "(nome) joga para mim" | D53: "(nome) joga para mim" | E53: "(nome) joga para mim" | F53: "(nome) joga para mim" | G53: "(nome) joga para mim" | H53: "(nome) joga para mim"
B55: AJUDA | C55: Gestual | D55: Gestual | E55: Gestual | F55: Gestual | G55: Gestual | H55: Gestual | I55: Visual | J55: Gestual | K55: Gestual | L55: Gestual | M55: Gestual | N55: Gestual | O55: Gestual | P55: Física Total | Q55: Visual | R55: Não Faz | S55: Gestual | T55: Gestual | U55: Gestual | V55: Gestual | W55: Gestual | X55: Gestual | Y55: Gestual | Z55: Gestual | AA55: Gestual | AB55: Gestual | AC55: Gestual | AD55: Gestual | AE55: Gestual | AF55: Gestual | AG55: Gestual
B56: ACERTOS | C56: 20 | D56: 20 | E56: 20 | F56: 20 | G56: 20 | H56: 20 | I56: 20 | J56: 20 | K56: 20 | L56: 20 | M56: 20 | N56: 20 | O56: 20 | P56: 9 | Q56: 20 | R56: 20 | S56: 20 | T56: 20 | U56: 20 | V56: 20 | W56: 20 | X56: 20 | Y56: 20 | Z56: 20 | AA56: 20 | AB56: 20 | AC56: 20 | AD56: 20 | AE56: 20 | AF56: 20 | AG56: 20 | AH56: =SUM(C56:AG56) -> 609
B57: TENTATIVAS | C57: 30 | D57: 30 | E57: 30 | F57: 30 | G57: 30 | H57: 30 | I57: 30 | J57: 30 | K57: 30 | L57: 30 | M57: 30 | N57: 30 | O57: 30 | P57: 10 | Q57: 30 | R57: 30 | S57: 30 | T57: 30 | U57: 30 | V57: 30 | W57: 30 | X57: 30 | Y57: 30 | Z57: 30 | AA57: 30 | AB57: 30 | AC57: 30 | AD57: 30 | AE57: 30 | AF57: 30 | AG57: 30 | AH57: =SUM(C57:AG57) -> 910
B58: % ACERTOS | C58: =C56/C57 -> 0.66666667 | D58: =D56/D57 -> 0.66666667 | E58: =E56/E57 -> 0.66666667 | F58: =F56/F57 -> 0.66666667 | G58: =G56/G57 -> 0.66666667 | H58: =H56/H57 -> 0.66666667 | I58: =I56/I57 -> 0.66666667 | J58: =J56/J57 -> 0.66666667 | ... AH58: =AH56/AH57 -> 0.66923077
B60: PROGRAMA 5 | C60: Brincar Social | D60: Brincar Social | E60: Brincar Social | F60: Brincar Social | G60: Brincar Social | H60: Brincar Social | AH60: % TOTAL ACERTOS
B61: Sd | C61: Bola | D61: Bola | E61: Bola | F61: Bola | G61: Bola | H61: Bola
C62: "(nome) joga para mim" | D62: "(nome) joga para mim" | E62: "(nome) joga para mim" | F62: "(nome) joga para mim" | G62: "(nome) joga para mim" | H62: "(nome) joga para mim"
B64: AJUDA | C64: Gestual | D64: Gestual | E64: Gestual | F64: Gestual | G64: Gestual | H64: Gestual | I64: Visual | J64: Gestual | K64: Gestual | L64: Gestual | M64: Gestual | N64: Gestual | O64: Gestual | P64: Física Total | Q64: Visual | R64: Não Faz | S64: Gestual | T64: Gestual | U64: Gestual | V64: Gestual | W64: Gestual | X64: Gestual | Y64: Gestual | Z64: Gestual | AA64: Gestual | AB64: Gestual | AC64: Gestual | AD64: Gestual | AE64: Gestual | AF64: Gestual | AG64: Gestual
B65: ACERTOS | C65: 20 | D65: 20 | E65: 20 | F65: 20 | G65: 20 | H65: 20 | I65: 20 | J65: 20 | K65: 20 | L65: 20 | M65: 20 | N65: 20 | O65: 20 | P65: 9 | Q65: 20 | R65: 20 | S65: 20 | T65: 20 | U65: 20 | V65: 20 | W65: 20 | X65: 20 | Y65: 20 | Z65: 20 | AA65: 20 | AB65: 20 | AC65: 20 | AD65: 20 | AE65: 20 | AF65: 20 | AG65: 20 | AH65: =SUM(C65:AG65) -> 609
...

Sheet mês 4
B1: TODOS OS DIREITOS RESERVADOS À PLANILHA E CIA - Nº DE SÉRIE DO USUÁRIO: 0024001813| PROIBIDO O RATEIO, A COMERCIALIZAÇÃO E A REPRODUÇÃO DESSE MATERIAL PROIBIDO O USO DESSE MATERIAL POR MAIS DE UM USUÁRIO, SALVO SE A COMPRA TIVER OCORRIDO ATRAVÉS DO CNPJ DA CLÍNICA. MULTIPROFISSIONAL.
B3: REGISTRO DE PROGRAMAS - 2025
B5: Criança: | C5: PROGRAMA 1 | D5: Imitação | F5: PROGRAMA 2 | G5: Brincar Social | I5: PROGRAMA 3 | L5: PROGRAMA 4 | O5: PROGRAMA 5 | R5: PROGRAMA 6 | U5: PROGRAMA 7 | X5: PROGRAMA 8 | AA5: PROGRAMA 9 | AD5: PROGRAMA 10
B6: Lucas ABC
B7: Aplicador:
B8: Natasha XYZ
B22: * Preencha na tabela todos os dados coletados nos treinos com a criança. Não preencha a linha em roxo de %acertos, que possui fórmula.
B23: Data | C23: 45778 | D23: 45779 | E23: 45780 | F23: 45781 | G23: 45782 | H23: 45783 | I23: 45784 | J23: 45785 | K23: 45786 | L23: 45787 | M23: 45788 | N23: 45789 | O23: 45790 | P23: 45791 | Q23: 45792 | R23: 45793 | S23: 45794 | T23: 45795 | U23: 45796 | V23: 45797 | W23: 45798 | X23: 45799 | Y23: 45800 | Z23: 45801 | AA23: 45802 | AB23: 45803 | AC23: 45804 | AD23: 45805 | AE23: 45806 | AF23: 45807 | AG23: 45808 | AH23: % TOTAL ACERTOS
B24: PROGRAMA 1 | C24: Imitação | D24: Imitação
B25: Sd | C25: Carro | D25: Bola
C26: "(nome) faz igual" | D26: "(nome) faz igual"
B28: AJUDA | C28: Gestual | D28: Gestual | E28: Visual | F28: Física Parcial | G28: Faz Independente | H28: Gestual | I28: Gestual | J28: Gestual | K28: Gestual | L28: Gestual | M28: Gestual | N28: Gestual | O28: Gestual | P28: Gestual | Q28: Gestual | R28: Gestual | S28: Gestual | T28: Gestual | U28: Gestual | V28: Gestual | W28: Gestual | X28: Gestual | Y28: Gestual | Z28: Gestual | AA28: Gestual | AB28: Gestual | AC28: Gestual | AD28: Gestual | AE28: Gestual | AF28: Gestual | AG28: Gestual
B29: ACERTOS | C29: 10 | D29: 10 | E29: 10 | F29: 10 | G29: 10 | H29: 10 | I29: 10 | J29: 10 | K29: 10 | L29: 10 | M29: 10 | N29: 10 | O29: 10 | P29: 10 | Q29: 10 | R29: 10 | S29: 10 | T29: 10 | U29: 10 | V29: 10 | W29: 10 | X29: 10 | Y29: 10 | Z29: 10 | AA29: 10 | AB29: 10 | AC29: 10 | AD29: 10 | AE29: 10 | AF29: 10 | AG29: 10 | AH29: =SUM(C29:AG29) -> 310
B30: TENTATIVAS | C30: 30 | D30: 30 | E30: 30 | F30: 30 | G30: 30 | H30: 30 | I30: 30 | J30: 30 | K30: 30 | L30: 30 | M30: 30 | N30: 30 | O30: 30 | P30: 30 | Q30: 30 | R30: 30 | S30: 30 | T30: 30 | U30: 30 | V30: 30 | W30: 30 | X30: 30 | Y30: 30 | Z30: 30 | AA30: 30 | AB30: 30 | AC30: 30 | AD30: 30 | AE30: 30 | AF30: 30 | AG30: 30 | AH30: =SUM(C30:AG30) -> 930
B31: % ACERTOS | C31: =C29/C30 -> 0.33333333 | D31: =D29/D30 -> 0.33333333 | E31: =E29/E30 -> 0.33333333 | F31: =F29/F30 -> 0.33333333 | G31: =G29/G30 -> 0.33333333 | H31: =H29/H30 -> 0.33333333 | I31: =I29/I30 -> 0.33333333 | J31: =J29/J30 -> 0.33333333 | ... AH31: =AH29/AH30 -> 0.33333333
B33: PROGRAMA 2 | C33: Brincar Social | D33: Brincar Social | E33: Brincar Social | F33: Brincar Social | G33: Brincar Social | H33: Brincar Social | AH33: % TOTAL ACERTOS
B34: Sd
B37: AJUDA | K37: Gestual | L37: Gestual | M37: Gestual | N37: Gestual | O37: Gestual | P37: Física Total | Q37: Visual | R37: Não Faz | S37: Gestual | T37: Gestual | U37: Gestual | V37: Gestual | W37: Gestual | X37: Gestual | Y37: Gestual | Z37: Gestual | AA37: Gestual | AB37: Gestual | AC37: Gestual | AD37: Gestual | AE37: Gestual | AF37: Gestual | AG37: Gestual
B38: ACERTOS | C38: 10 | D38: 10 | E38: 10 | F38: 10 | G38: 10 | H38: 10 | I38: 10 | J38: 10 | K38: 10 | L38: 10 | M38: 10 | N38: 10 | O38: 10 | P38: 10 | Q38: 10 | R38: 10 | S38: 10 | T38: 10 | U38: 10 | V38: 10 | W38: 10 | X38: 10 | Y38: 10 | Z38: 10 | AA38: 10 | AB38: 10 | AC38: 10 | AD38: 10 | AE38: 10 | AF38: 10 | AG38: 10 | AH38: =SUM(C38:AG38) -> 310
B39: TENTATIVAS | C39: 30 | D39: 30 | E39: 30 | F39: 30 | G39: 30 | H39: 30 | I39: 30 | J39: 30 | K39: 30 | L39: 30 | M39: 30 | N39: 30 | O39: 30 | P39: 30 | Q39: 30 | R39: 30 | S39: 30 | T39: 30 | U39: 30 | V39: 30 | W39: 30 | X39: 30 | Y39: 30 | Z39: 30 | AA39: 30 | AB39: 30 | AC39: 30 | AD39: 30 | AE39: 30 | AF39: 30 | AG39: 30 | AH39: =SUM(C39:AG39) -> 930
B40: % ACERTOS | C40: =C38/C39 -> 0.33333333 | D40: =D38/D39 -> 0.33333333 | E40: =E38/E39 -> 0.33333333 | F40: =F38/F39 -> 0.33333333 | G40: =G38/G39 -> 0.33333333 | H40: =H38/H39 -> 0.33333333 | I40: =I38/I39 -> 0.33333333 | J40: =J38/J39 -> 0.33333333 | ... AH40: =AH38/AH39 -> 0.33333333
B42: PROGRAMA 3 | C42: Brincar Social | D42: Brincar Social | E42: Brincar Social | F42: Brincar Social | G42: Brincar Social | H42: Brincar Social | AH42: % TOTAL ACERTOS
B43: Sd | C43: Bola | D43: Bola | E43: Bola | F43: Bola | G43: Bola | H43: Bola
C44: "(nome) joga para mim" | D44: "(nome) joga para mim" | E44: "(nome) joga para mim" | F44: "(nome) joga para mim" | G44: "(nome) joga para mim" | H44: "(nome) joga para mim"
B46: AJUDA | C46: Gestual | D46: Gestual | E46: Gestual | F46: Gestual | G46: Gestual | H46: Gestual | I46: Visual | J46: Gestual | K46: Gestual | L46: Gestual | M46: Gestual | N46: Gestual | O46: Gestual | P46: Física Total | Q46: Visual | R46: Não Faz | S46: Gestual | T46: Gestual | U46: Gestual | V46: Gestual | W46: Gestual | X46: Gestual | Y46: Gestual | Z46: Gestual | AA46: Gestual | AB46: Gestual | AC46: Gestual | AD46: Gestual | AE46: Gestual | AF46: Gestual | AG46: Gestual
B47: ACERTOS | C47: 10 | D47: 10 | E47: 10 | F47: 10 | G47: 10 | H47: 10 | I47: 10 | J47: 10 | K47: 10 | L47: 10 | M47: 10 | N47: 10 | O47: 10 | P47: 10 | Q47: 10 | R47: 10 | S47: 10 | T47: 10 | U47: 10 | V47: 10 | W47: 10 | X47: 10 | Y47: 10 | Z47: 10 | AA47: 10 | AB47: 10 | AC47: 10 | AD47: 10 | AE47: 10 | AF47: 10 | AG47: 10 | AH47: =SUM(C47:AG47) -> 310
B48: TENTATIVAS | C48: 30 | D48: 30 | E48: 30 | F48: 30 | G48: 30 | H48: 30 | I48: 30 | J48: 30 | K48: 30 | L48: 30 | M48: 30 | N48: 30 | O48: 30 | P48: 30 | Q48: 30 | R48: 30 | S48: 30 | T48: 30 | U48: 30 | V48: 30 | W48: 30 | X48: 30 | Y48: 30 | Z48: 30 | AA48: 30 | AB48: 30 | AC48: 30 | AD48: 30 | AE48: 30 | AF48: 30 | AG48: 30 | AH48: =SUM(C48:AG48) -> 930
B49: % ACERTOS | C49: =C47/C48 -> 0.33333333 | D49: =D47/D48 -> 0.33333333 | E49: =E47/E48 -> 0.33333333 | F49: =F47/F48 -> 0.33333333 | G49: =G47/G48 -> 0.33333333 | H49: =H47/H48 -> 0.33333333 | I49: =I47/I48 -> 0.33333333 | J49: =J47/J48 -> 0.33333333 | ... AH49: =AH47/AH48 -> 0.33333333
B51: PROGRAMA 4 | C51: Brincar Social | D51: Brincar Social | E51: Brincar Social | F51: Brincar Social | G51: Brincar Social | H51: Brincar Social | AH51: % TOTAL ACERTOS
B52: Sd | C52: Bola | D52: Bola | E52: Bola | F52: Bola | G52: Bola | H52: Bola
C53: "(nome) joga para mim" | D53: "(nome) joga para mim" | E53: "(nome) joga para mim" | F53: "(nome) joga para mim" | G53: "(nome) joga para mim" | H53: "(nome) joga para mim"
B55: AJUDA | C55: Gestual | D55: Gestual | E55: Gestual | F55: Gestual | G55: Gestual | H55: Gestual | I55: Visual | J55: Gestual | K55: Gestual | L55: Gestual | M55: Gestual | N55: Gestual | O55: Gestual | P55: Física Total | Q55: Visual | R55: Não Faz | S55: Gestual | T55: Gestual | U55: Gestual | V55: Gestual | W55: Gestual | X55: Gestual | Y55: Gestual | Z55: Gestual | AA55: Gestual | AB55: Gestual | AC55: Gestual | AD55: Gestual | AE55: Gestual | AF55: Gestual | AG55: Gestual
B56: ACERTOS | C56: 10 | D56: 10 | E56: 10 | F56: 10 | G56: 10 | H56: 10 | I56: 10 | J56: 10 | K56: 10 | L56: 10 | M56: 10 | N56: 10 | O56: 10 | P56: 10 | Q56: 10 | R56: 10 | S56: 10 | T56: 10 | U56: 10 | V56: 10 | W56: 10 | X56: 10 | Y56: 10 | Z56: 10 | AA56: 10 | AB56: 10 | AC56: 10 | AD56: 10 | AE56: 10 | AF56: 10 | AG56: 10 | AH56: =SUM(C56:AG56) -> 310
B57: TENTATIVAS | C57: 30 | D57: 30 | E57: 30 | F57: 30 | G57: 30 | H57: 30 | I57: 30 | J57: 30 | K57: 30 | L57: 30 | M57: 30 | N57: 30 | O57: 30 | P57: 30 | Q57: 30 | R57: 30 | S57: 30 | T57: 30 | U57: 30 | V57: 30 | W57: 30 | X57: 30 | Y57: 30 | Z57: 30 | AA57: 30 | AB57: 30 | AC57: 30 | AD57: 30 | AE57: 30 | AF57: 30 | AG57: 30 | AH57: =SUM(C57:AG57) -> 930
B58: % ACERTOS | C58: =C56/C57 -> 0.33333333 | D58: =D56/D57 -> 0.33333333 | E58: =E56/E57 -> 0.33333333 | F58: =F56/F57 -> 0.33333333 | G58: =G56/G57 -> 0.33333333 | H58: =H56/H57 -> 0.33333333 | I58: =I56/I57 -> 0.33333333 | J58: =J56/J57 -> 0.33333333 | ... AH58: =AH56/AH57 -> 0.33333333
B60: PROGRAMA 5 | C60: Brincar Social | D60: Brincar Social | E60: Brincar Social | F60: Brincar Social | G60: Brincar Social | H60: Brincar Social | AH60: % TOTAL ACERTOS
B61: Sd | C61: Bola | D61: Bola | E61: Bola | F61: Bola | G61: Bola | H61: Bola
C62: "(nome) joga para mim" | D62: "(nome) joga para mim" | E62: "(nome) joga para mim" | F62: "(nome) joga para mim" | G62: "(nome) joga para mim" | H62: "(nome) joga para mim"
B64: AJUDA | C64: Gestual | D64: Gestual | E64: Gestual | F64: Gestual | G64: Gestual | H64: Gestual | I64: Visual | J64: Gestual | K64: Gestual | L64: Gestual | M64: Gestual | N64: Gestual | O64: Gestual | P64: Física Total | Q64: Visual | R64: Não Faz | S64: Gestual | T64: Gestual | U64: Gestual | V64: Gestual | W64: Gestual | X64: Gestual | Y64: Gestual | Z64: Gestual | AA64: Gestual | AB64: Gestual | AC64: Gestual | AD64: Gestual | AE64: Gestual | AF64: Gestual | AG64: Gestual
B65: ACERTOS | C65: 10 | D65: 10 | E65: 10 | F65: 10 | G65: 10 | H65: 10 | I65: 10 | J65: 10 | K65: 10 | L65: 10 | M65: 10 | N65: 10 | O65: 10 | P65: 10 | Q65: 10 | R65: 10 | S65: 10 | T65: 10 | U65: 10 | V65: 10 | W65: 10 | X65: 10 | Y65: 10 | Z65: 10 | AA65: 10 | AB65: 10 | AC65: 10 | AD65: 10 | AE65: 10 | AF65: 10 | AG65: 10 | AH65: =SUM(C65:AG65) -> 310
...

Sheet CONSOLIDADO
B2: REGISTRO DE PROGRAMAS - 2025
B4: * Na tabela abaixo, não é necessário o preenchimento, pois os dados são automáticos, exceto o título do programa que você pode preencher se preferir.
C5: Título | D5: % Total de Acertos
B6: Programas | D6: Janeiro | E6: Fevereiro | F6: Março | G6: Abril
B7: Programa 1 | C7: Imitação | D7: ='mês 1'!AH31 -> 0.77714286 | E7: ='mês 2'!AG31 -> 0.77647059 | F7: ='mês 3'!AH31 -> 0.77714286 | G7: ='mês 4'!AH31 -> 0.33333333
B8: Programa 2 | C8: Brincar Social | D8: ='mês 1'!AH40 -> 0.66923077 | E8: ='mês 2'!AG40 -> 0.66931818 | F8: ='mês 3'!AH40 -> 0.67014925 | G8: ='mês 4'!AH40 -> 0.33333333
B9: Programa 3 | D9: ='mês 1'!AH49 -> 0.66923077 | E9: ='mês 2'!AG49 -> 0.66931818 | F9: ='mês 3'!AH49 -> 0.66923077 | G9: ='mês 4'!AH49 -> 0.33333333
B10: Programa 4 | D10: ='mês 1'!AH58 -> 0.66923077 | E10: ='mês 2'!AG58 -> 0.66931818 | F10: ='mês 3'!AH58 -> 0.66923077 | G10: ='mês 4'!AH58 -> 0.33333333
B11: Programa 5 | D11: ='mês 1'!AH67 -> 0.66923077 | E11: ='mês 2'!AG67 -> 0.66931818 | F11: ='mês 3'!AH67 -> 0.66923077 | G11: ='mês 4'!AH67 -> 0.33333333
B12: Programa 6 | D12: ='mês 1'!AH76 -> 0.66923077 | E12: ='mês 2'!AG76 -> 0.66931818 | F12: ='mês 3'!AH76 -> 0.66923077 | G12: ='mês 4'!AH76 -> 0.33333333
B13: Programa 7 | D13: ='mês 1'!AH85 -> 0.66923077 | E13: ='mês 2'!AG85 -> 0.66931818 | F13: ='mês 3'!AH85 -> 0.66923077 | G13: ='mês 4'!AH85 -> 0.33333333
B14: Programa 8 | D14: ='mês 1'!AH94 -> 0.66923077 | E14: ='mês 2'!AG94 -> 0.66931818 | F14: ='mês 3'!AH94 -> 0.66923077 | G14: ='mês 4'!AH94 -> 0.33333333
B15: Programa 9 | D15: ='mês 1'!AH103 -> 0.66923077 | E15: ='mês 2'!AG103 -> 0.66931818 | F15: ='mês 3'!AH103 -> 0.66923077 | G15: ='mês 4'!AH103 -> 0.33333333
B16: Programa 10 | D16: ='mês 1'!AH112 -> 0.67681499 | E16: ='mês 2'!AG112 -> 0.67718447 | F16: ='mês 3'!AH112 -> 0.66923077 | G16: ='mês 4'!AH112 -> 0.33333333

Sheet Modelo Relatório
C6: Fazer modelo de relatório padrão e puxar gráfico automatico
C7: ver modelo Regina Bergamme
C8: Ver modelo Henrique
C9: Ver modelo Cia do autismo
